Workbook

Sheet To Be Quote Fields
A1: Jira Id | B1: RCA Label | C1: RCA API | D1: Created By | E1: Conga API | F1: Standard/Existing/New | G1: Logic in RCA | H1: Related Components | I1: Approval/Product/Pricing
B2: Account Name | C2: AccountId | F2: Standard
B3: Additional To | C3: AdditionalAddress | F3: Standard
B4: Additional To Name | C4: AdditionalName | F4: Standard
B5: Adjustment Type | C5: Adjustment_Type__c | D5: Harcharan | F5: New
B6: Adjustment Distribution Logic | C6: AdjustmentDistributionLogic | F6: Standard
B7: Annual Commit Approval Partner Program | C7: Annual_Commit_Approval_Partner_Program__c | D7: Harcharan
B8: Applied Discount | C8: AppliedDiscount | F8: Standard
B9: Applied Discount Amount | C9: AppliedDiscountAmount | F9: Standard
B10: NSP Approval # | C10: Approval__c | F10: Exisitng
B11: NSP Approval Date | C11: Approval_Date__c | F11: Exisitng
B12: 承認申請日時 | C12: ApprovalRequestDateTime__c | F12: Exisitng
B13: 承認申請時利益率 | C13: ApprovalRequestProfitsRate__c | F13: Exisitng
B14: 備考（メモ） | C14: bikou_memo__c | F14: Exisitng
B15: Billing Frequency Modified | C15: Billing_Frequency_Modified__c | D15: Harcharan | F15: New
B16: Bill To | C16: BillingAddress | F16: Standard
B17: Bill To Name | C17: BillingName | F17: Standard
B18: Bill To Contact | C18: BillToContactId | F18: Standard
B19: Calculation Status | C19: CalculationStatus | F19: Standard
B20: Can Create Quote Line Items | C20: CanCreateQuoteLineItems | F20: Standard
B21: case status | C21: case_status__c | D21: Srilekha
B22: Channel | C22: Channel__c | F22: Exisitng
B23: Charge Type | C23: Charge_Type__c | D23: Harcharan
B24: Clone Quote ID | C24: Clone_Quote_ID__c | F24: Exisitng
B25: Clone Quote Status | C25: Clone_Quote_Status__c | F25: Exisitng
B26: Clone Quote Total Price | C26: Clone_Quote_Total__c | F26: Exisitng
B27: Clone Quote Total Price Diff | C27: Clone_Quote_Total_Price_Diff__c | F27: Exisitng
B28: Company | C28: Company__c | F28: Exisitng
B29: Console | C29: Console__c | D29: Harcharan
B30: Contact Name | C30: ContactId | F30: Standard
B31: Contract | C31: ContractId | F31: Standard
B32: 作成日 | C32: CreateDate__c | F32: Exisitng
B33: Quote Currency | C33: CurrencyIsoCode | F33: Standard
B34: Opp Reg # | C34: DAN__c | F34: Exisitng
B35: Opp Reg Expiration Date | C35: DAN_Expiration_Date__c | F35: Exisitng
B36: Deal ID | C36: Deal_ID__c | F36: Exisitng
B37: Deal Reg Discount | C37: Deal_Reg_Discount__c | F37: Exisitng
B38: Description | C38: Description | F38: Standard
B39: DigiCert Email | C39: DigiCert_Email__c | F39: Exisitng
B40: DigiCert Phone | C40: DigiCert_Phone__c | F40: Exisitng
...

Sheet QuoteProposal - Fields
A1: Object | C1: Quote/Proposal
A2: API Name | C2: Apttus_Proposal__Proposal__c
O3: Field-Level Security for Profile
A4: NO | B4: Field Label | C4: API Name | D4: Data Type | E4: Length | F4: Field Type | G4: Required | H4: Picklist Values | I4: Formula | J4: Extend ID | K4: Track History | L4: Description | M4: Help Text | N4: Proposal Layout V2 | O4: Admin | P4: Customer Surveys Profile | Q4: DC Customer Support Portal | R4: DC Legal | S4: DC MM NetNew Sales | T4: DC NetNew Sales | U4: DC Order Management | V4: DC SDR NetNew Sales | W4: DC Sales | X4: DC Sales Ops | Y4: DC Sales Supervisor | Z4: DC Services | AA4: DC Services Supervisor | AB4: DC System Admin - System Accounts | AC4: DigiCert Support Portal Profile | AD4: Live Agent Chat Profile | AE4: Mocana Customer Service Desk | AF4: Mocana Support Desk Profile | AG4: Read Only | AH4: Salesforce API Only System Integrations | AI4: Vercara (Read Only)
A5: 1 | B5: Record ID | C5: Id | D5: id | F5: Standard | G5: Required | N5: =VLOOKUP(B5,'Sheet 1'!$B$2:$C$108,2,FALSE) -> #N/A | O5: - | P5: - | Q5: - | R5: - | S5: - | T5: - | U5: - | V5: - | W5: - | X5: - | Y5: - | Z5: - | AA5: - | AB5: - | AC5: - | AD5: - | AE5: - | AF5: - | AG5: - | AH5: - | AI5: -
A6: 2 | B6: Owner ID | C6: OwnerId | D6: Lookup (Group,User) | F6: Standard | G6: Required | N6: =VLOOKUP(B6,'Sheet 1'!$B$2:$C$108,2,FALSE) -> #N/A | O6: - | P6: - | Q6: - | R6: - | S6: - | T6: - | U6: - | V6: - | W6: - | X6: - | Y6: - | Z6: - | AA6: - | AB6: - | AC6: - | AD6: - | AE6: - | AF6: - | AG6: - | AH6: - | AI6: -
A7: 3 | B7: Deleted | C7: IsDeleted | D7: Checkbox | F7: Standard | N7: =VLOOKUP(B7,'Sheet 1'!$B$2:$C$108,2,FALSE) -> #N/A | O7: - | P7: - | Q7: - | R7: - | S7: - | T7: - | U7: - | V7: - | W7: - | X7: - | Y7: - | Z7: - | AA7: - | AB7: - | AC7: - | AD7: - | AE7: - | AF7: - | AG7: - | AH7: - | AI7: -
A8: 4 | B8: Proposal ID | C8: Name | D8: Auto Number | E8: 80 | F8: Standard | G8: Required | N8: =VLOOKUP(B8,'Sheet 1'!$B$2:$C$108,2,FALSE) -> V2 | O8: - | P8: - | Q8: - | R8: - | S8: - | T8: - | U8: - | V8: - | W8: - | X8: - | Y8: - | Z8: - | AA8: - | AB8: - | AC8: - | AD8: - | AE8: - | AF8: - | AG8: - | AH8: - | AI8: -
A9: 5 | B9: Currency ISO Code | C9: CurrencyIsoCode | D9: Picklist | F9: Standard | H9: AUD;BMD;BRL;GBP;CAD;CLP;CNY;DKK;EUR;HKD;INR;ILS;JPY;KRW;MXN;NZD;NOK;PLN;RUB;SAR;SGD;ZAR;SEK;CHF;TWD;USD;AED | N9: =VLOOKUP(B9,'Sheet 1'!$B$2:$C$108,2,FALSE) -> #N/A | O9: - | P9: - | Q9: - | R9: - | S9: - | T9: - | U9: - | V9: - | W9: - | X9: - | Y9: - | Z9: - | AA9: - | AB9: - | AC9: - | AD9: - | AE9: - | AF9: - | AG9: - | AH9: - | AI9: -
A10: 6 | B10: Record Type ID | C10: RecordTypeId | D10: Lookup (Record Type) | F10: Standard | N10: =VLOOKUP(B10,'Sheet 1'!$B$2:$C$108,2,FALSE) -> #N/A | O10: - | P10: - | Q10: - | R10: - | S10: - | T10: - | U10: - | V10: - | W10: - | X10: - | Y10: - | Z10: - | AA10: - | AB10: - | AC10: - | AD10: - | AE10: - | AF10: - | AG10: - | AH10: - | AI10: -
A11: 7 | B11: Created Date | C11: CreatedDate | D11: Date/Time | F11: Standard | G11: Required | N11: =VLOOKUP(B11,'Sheet 1'!$B$2:$C$108,2,FALSE) -> #N/A | O11: - | P11: - | Q11: - | R11: - | S11: - | T11: - | U11: - | V11: - | W11: - | X11: - | Y11: - | Z11: - | AA11: - | AB11: - | AC11: - | AD11: - | AE11: - | AF11: - | AG11: - | AH11: - | AI11: -
A12: 8 | B12: Created By ID | C12: CreatedById | D12: Lookup (User) | F12: Standard | G12: Required | N12: =VLOOKUP(B12,'Sheet 1'!$B$2:$C$108,2,FALSE) -> #N/A | O12: - | P12: - | Q12: - | R12: - | S12: - | T12: - | U12: - | V12: - | W12: - | X12: - | Y12: - | Z12: - | AA12: - | AB12: - | AC12: - | AD12: - | AE12: - | AF12: - | AG12: - | AH12: - | AI12: -
A13: 9 | B13: Last Modified Date | C13: LastModifiedDate | D13: Date/Time | F13: Standard | G13: Required | N13: =VLOOKUP(B13,'Sheet 1'!$B$2:$C$108,2,FALSE) -> #N/A | O13: - | P13: - | Q13: - | R13: - | S13: - | T13: - | U13: - | V13: - | W13: - | X13: - | Y13: - | Z13: - | AA13: - | AB13: - | AC13: - | AD13: - | AE13: - | AF13: - | AG13: - | AH13: - | AI13: -
A14: 10 | B14: Last Modified By ID | C14: LastModifiedById | D14: Lookup (User) | F14: Standard | G14: Required | N14: =VLOOKUP(B14,'Sheet 1'!$B$2:$C$108,2,FALSE) -> #N/A | O14: - | P14: - | Q14: - | R14: - | S14: - | T14: - | U14: - | V14: - | W14: - | X14: - | Y14: - | Z14: - | AA14: - | AB14: - | AC14: - | AD14: - | AE14: - | AF14: - | AG14: - | AH14: - | AI14: -
A15: 11 | B15: System Modstamp | C15: SystemModstamp | D15: Date/Time | F15: Standard | G15: Required | N15: =VLOOKUP(B15,'Sheet 1'!$B$2:$C$108,2,FALSE) -> #N/A | O15: - | P15: - | Q15: - | R15: - | S15: - | T15: - | U15: - | V15: - | W15: - | X15: - | Y15: - | Z15: - | AA15: - | AB15: - | AC15: - | AD15: - | AE15: - | AF15: - | AG15: - | AH15: - | AI15: -
A16: 12 | B16: Last Activity Date | C16: LastActivityDate | D16: Date | F16: Standard | N16: =VLOOKUP(B16,'Sheet 1'!$B$2:$C$108,2,FALSE) -> #N/A | O16: - | P16: - | Q16: - | R16: - | S16: - | T16: - | U16: - | V16: - | W16: - | X16: - | Y16: - | Z16: - | AA16: - | AB16: - | AC16: - | AD16: - | AE16: - | AF16: - | AG16: - | AH16: - | AI16: -
A17: 13 | B17: Last Viewed Date | C17: LastViewedDate | D17: Date/Time | F17: Standard | N17: =VLOOKUP(B17,'Sheet 1'!$B$2:$C$108,2,FALSE) -> #N/A | O17: - | P17: - | Q17: - | R17: - | S17: - | T17: - | U17: - | V17: - | W17: - | X17: - | Y17: - | Z17: - | AA17: - | AB17: - | AC17: - | AD17: - | AE17: - | AF17: - | AG17: - | AH17: - | AI17: -
A18: 14 | B18: Last Referenced Date | C18: LastReferencedDate | D18: Date/Time | F18: Standard | N18: =VLOOKUP(B18,'Sheet 1'!$B$2:$C$108,2,FALSE) -> #N/A | O18: - | P18: - | Q18: - | R18: - | S18: - | T18: - | U18: - | V18: - | W18: - | X18: - | Y18: - | Z18: - | AA18: - | AB18: - | AC18: - | AD18: - | AE18: - | AF18: - | AG18: - | AH18: - | AI18: -
A19: 15 | B19: Account | C19: Apttus_Proposal__Account__c | D19: Lookup (Account) | F19: Custom | K19: ✓ | L19: Prospect Account | N19: =VLOOKUP(B19,'Sheet 1'!$B$2:$C$108,2,FALSE) -> V2 | O19: Editable | P19: Invisible | Q19: Invisible | R19: Editable | S19: Invisible | T19: Invisible | U19: Editable | V19: Editable | W19: Editable | X19: Editable | Y19: Editable | Z19: Editable | AA19: Editable | AB19: Editable | AC19: Invisible | AD19: Invisible | AE19: Editable | AF19: Invisible | AG19: Editable | AH19: Editable | AI19: Invisible
A20: 16 | B20: Approval Stage | C20: Apttus_Proposal__Approval_Stage__c | D20: Picklist | F20: Custom | H20: Draft;Approval Required;In Review;Approved;Generated;Presented;Accepted;Denied;Cancelled | K20: ✓ | L20: The proposal approval stage | N20: =VLOOKUP(B20,'Sheet 1'!$B$2:$C$108,2,FALSE) -> V2 | O20: Editable | P20: Invisible | Q20: Invisible | R20: Editable | S20: Invisible | T20: Invisible | U20: Editable | V20: Editable | W20: Editable | X20: Editable | Y20: Editable | Z20: Editable | AA20: Editable | AB20: Editable | AC20: Invisible | AD20: Invisible | AE20: Editable | AF20: Invisible | AG20: Editable | AH20: Editable | AI20: Invisible
A21: 17 | B21: Create Agreement | C21: Apttus_Proposal__CreateAgreement__c | D21: Formula (Text) | E21: 1300 | F21: Custom | I21: IF (ISPICKVAL(Apttus_Proposal__Approval_Stage__c, "Accepted") , IF($User.UIThemeDisplayed == 'Theme4d',HYPERLINK("/one/one.app#/alohaRedirect/apex/Apttus_Proposal__ProposalAgreementCreate?id="&Id, IMAGE("/resource/Apttus_Proposal__Button_CreateAgreement", "Create Agreement"),"_self"),HYPERLINK("/apex/Apttus_Proposal__ProposalAgreementCreate?id="&Id, IMAGE("/resource/Apttus_Proposal__Button_CreateAgreement", "Create Agreement"),"_self")), NULL) | L21: Create Agreement, if the proposal is accepted. | N21: =VLOOKUP(B21,'Sheet 1'!$B$2:$C$108,2,FALSE) -> #N/A | O21: Read-Only | P21: Invisible | Q21: Invisible | R21: Editable | S21: Invisible | T21: Invisible | U21: Read-Only | V21: Editable | W21: Read-Only | X21: Read-Only | Y21: Editable | Z21: Editable | AA21: Editable | AB21: Editable | AC21: Invisible | AD21: Invisible | AE21: Editable | AF21: Invisible | AG21: Editable | AH21: Editable | AI21: Invisible
A22: 18 | B22: Description | C22: Apttus_Proposal__Description__c | D22: Long Text Area | E22: 32000 | F22: Custom | L22: The proposal description | N22: =VLOOKUP(B22,'Sheet 1'!$B$2:$C$108,2,FALSE) -> V2 | O22: Editable | P22: Invisible | Q22: Invisible | R22: Editable | S22: Invisible | T22: Invisible | U22: Editable | V22: Editable | W22: Editable | X22: Editable | Y22: Editable | Z22: Editable | AA22: Editable | AB22: Editable | AC22: Invisible | AD22: Invisible | AE22: Editable | AF22: Invisible | AG22: Editable | AH22: Editable | AI22: Invisible
A23: 19 | B23: Discount % | C23: Apttus_Proposal__Discount_Percent__c | D23: Percent | F23: Custom | N23: =VLOOKUP(B23,'Sheet 1'!$B$2:$C$108,2,FALSE) -> #N/A | O23: Editable | P23: Invisible | Q23: Invisible | R23: Editable | S23: Invisible | T23: Invisible | U23: Editable | V23: Editable | W23: Editable | X23: Editable | Y23: Editable | Z23: Editable | AA23: Editable | AB23: Editable | AC23: Invisible | AD23: Invisible | AE23: Editable | AF23: Invisible | AG23: Editable | AH23: Editable | AI23: Invisible
A24: 20 | B24: Expected End Date | C24: Apttus_Proposal__ExpectedEndDate__c | D24: Date | F24: Custom | L24: The expected end date for products and services | N24: =VLOOKUP(B24,'Sheet 1'!$B$2:$C$108,2,FALSE) -> #N/A | O24: Editable | P24: Invisible | Q24: Invisible | R24: Editable | S24: Invisible | T24: Invisible | U24: Editable | V24: Editable | W24: Editable | X24: Editable | Y24: Editable | Z24: Editable | AA24: Editable | AB24: Editable | AC24: Invisible | AD24: Invisible | AE24: Editable | AF24: Invisible | AG24: Editable | AH24: Editable | AI24: Invisible
A25: 21 | B25: Expected Start Date | C25: Apttus_Proposal__ExpectedStartDate__c | D25: Date | F25: Custom | L25: The expected start date for products and services | N25: =VLOOKUP(B25,'Sheet 1'!$B$2:$C$108,2,FALSE) -> V2 | O25: Editable | P25: Invisible | Q25: Invisible | R25: Editable | S25: Invisible | T25: Invisible | U25: Editable | V25: Editable | W25: Editable | X25: Editable | Y25: Editable | Z25: Editable | AA25: Editable | AB25: Editable | AC25: Invisible | AD25: Invisible | AE25: Editable | AF25: Invisible | AG25: Editable | AH25: Editable | AI25: Invisible
A26: 22 | B26: Generate | C26: Apttus_Proposal__Generate__c | D26: Formula (Text) | E26: 1300 | F26: Custom | I26: IF (Apttus_Proposal__ReadyToGenerate__c, IF($User.UIThemeDisplayed == 'Theme4d',HYPERLINK("/one/one.app#/alohaRedirect/apex/Apttus_Proposal__ProposalGenerate?id="&Id, IMAGE("/resource/Apttus_Proposal__Button_Generate", "Generate"),"_self"),HYPERLINK("/apex/Apttus_Proposal__ProposalGenerate?id="&Id, IMAGE("/resource/Apttus_Proposal__Button_Generate", "Generate"),"_self")), NULL) | L26: Generate a quote/proposal | M26: Generate a quote/proposal | N26: =VLOOKUP(B26,'Sheet 1'!$B$2:$C$108,2,FALSE) -> #N/A | O26: Read-Only | P26: Invisible | Q26: Invisible | R26: Editable | S26: Invisible | T26: Invisible | U26: Read-Only | V26: Editable | W26: Read-Only | X26: Read-Only | Y26: Editable | Z26: Editable | AA26: Editable | AB26: Editable | AC26: Invisible | AD26: Invisible | AE26: Editable | AF26: Invisible | AG26: Editable | AH26: Editable | AI26: Invisible
A27: 23 | B27: Grand Total | C27: Apttus_Proposal__Grand_Total__c | D27: Formula (Currency) | F27: Custom | I27: Apttus_Proposal__Net_Amount__c + Apttus_Proposal__Shipping_Handling__c + Apttus_Proposal__Sales_Tax_Amount__c | N27: =VLOOKUP(B27,'Sheet 1'!$B$2:$C$108,2,FALSE) -> #N/A | O27: Read-Only | P27: Invisible | Q27: Invisible | R27: Editable | S27: Invisible | T27: Invisible | U27: Read-Only | V27: Editable | W27: Read-Only | X27: Read-Only | Y27: Editable | Z27: Editable | AA27: Editable | AB27: Editable | AC27: Invisible | AD27: Invisible | AE27: Editable | AF27: Invisible | AG27: Editable | AH27: Editable | AI27: Invisible
A28: 24 | B28: Internal Deadline | C28: Apttus_Proposal__Internal_Deadline__c | D28: Date | F28: Custom | N28: =VLOOKUP(B28,'Sheet 1'!$B$2:$C$108,2,FALSE) -> #N/A | O28: Editable | P28: Invisible | Q28: Invisible | R28: Editable | S28: Invisible | T28: Invisible | U28: Editable | V28: Editable | W28: Editable | X28: Editable | Y28: Editable | Z28: Editable | AA28: Editable | AB28: Editable | AC28: Invisible | AD28: Invisible | AE28: Editable | AF28: Invisible | AG28: Editable | AH28: Editable | AI28: Invisible
A29: 25 | B29: Make Primary | C29: Apttus_Proposal__MakePrimary__c | D29: Formula (Text) | E29: 1300 | F29: Custom | I29: IF (AND(LEN(Apttus_Proposal__Opportunity__c ) > 0, NOT(Apttus_Proposal__Primary__c)), HYPERLINK("/apex/Apttus_Proposal__ProposalMakePrimary?id="&Id, IMAGE("/resource/Apttus_Proposal__Button_MakePrimary", "Make Primary"),"_self"), NULL) | L29: Make the quote/proposal primary for the associated opportunity | N29: =VLOOKUP(B29,'Sheet 1'!$B$2:$C$108,2,FALSE) -> #N/A | O29: Read-Only | P29: Invisible | Q29: Invisible | R29: Editable | S29: Invisible | T29: Invisible | U29: Read-Only | V29: Editable | W29: Read-Only | X29: Read-Only | Y29: Editable | Z29: Editable | AA29: Editable | AB29: Editable | AC29: Invisible | AD29: Invisible | AE29: Editable | AF29: Invisible | AG29: Editable | AH29: Editable | AI29: Invisible
A30: 26 | B30: Net Amount | C30: Apttus_Proposal__Net_Amount__c | D30: Formula (Currency) | F30: Custom | I30: Apttus_Proposal__Amount__c * (1 - Apttus_Proposal__Discount_Percent__c ) | N30: =VLOOKUP(B30,'Sheet 1'!$B$2:$C$108,2,FALSE) -> #N/A | O30: Read-Only | P30: Invisible | Q30: Invisible | R30: Editable | S30: Invisible | T30: Invisible | U30: Read-Only | V30: Editable | W30: Read-Only | X30: Read-Only | Y30: Editable | Z30: Editable | AA30: Editable | AB30: Editable | AC30: Invisible | AD30: Invisible | AE30: Editable | AF30: Invisible | AG30: Editable | AH30: Editable | AI30: Invisible
A31: 27 | B31: Opportunity | C31: Apttus_Proposal__Opportunity__c | D31: Lookup (Opportunity) | F31: Custom | L31: The related opportunity | N31: =VLOOKUP(B31,'Sheet 1'!$B$2:$C$108,2,FALSE) -> V2 | O31: Editable | P31: Invisible | Q31: Invisible | R31: Editable | S31: Invisible | T31: Invisible | U31: Editable | V31: Editable | W31: Editable | X31: Editable | Y31: Editable | Z31: Editable | AA31: Editable | AB31: Editable | AC31: Invisible | AD31: Invisible | AE31: Editable | AF31: Invisible | AG31: Editable | AH31: Editable | AI31: Invisible
A32: 28 | B32: Payment Term | C32: Apttus_Proposal__Payment_Term__c | D32: Picklist | F32: Custom | H32: Net 30;Net 30 EoM | N32: =VLOOKUP(B32,'Sheet 1'!$B$2:$C$108,2,FALSE) -> V2 | O32: Editable | P32: Invisible | Q32: Invisible | R32: Editable | S32: Invisible | T32: Invisible | U32: Editable | V32: Editable | W32: Editable | X32: Editable | Y32: Editable | Z32: Editable | AA32: Editable | AB32: Editable | AC32: Invisible | AD32: Invisible | AE32: Editable | AF32: Invisible | AG32: Editable | AH32: Editable | AI32: Invisible
A33: 29 | B33: Present | C33: Apttus_Proposal__Present__c | D33: Formula (Text) | E33: 1300 | F33: Custom | I33: IF (Apttus_Proposal__ReadyToPresent__c, IF($User.UIThemeDisplayed == 'Theme4d',HYPERLINK("/one/one.app#/alohaRedirect/apex/Apttus_Proposal__ProposalPresent?id="&Id, IMAGE("/resource/Apttus_Proposal__Button_Present", "Present"),"_self"),HYPERLINK("/apex/Apttus_Proposal__ProposalPresent?id="&Id, IMAGE("/resource/Apttus_Proposal__Button_Present", "Present"),"_self")), NULL) | L33: Present the quote/proposal | N33: =VLOOKUP(B33,'Sheet 1'!$B$2:$C$108,2,FALSE) -> #N/A | O33: Read-Only | P33: Invisible | Q33: Invisible | R33: Editable | S33: Invisible | T33: Invisible | U33: Read-Only | V33: Editable | W33: Read-Only | X33: Read-Only | Y33: Editable | Z33: Editable | AA33: Editable | AB33: Editable | AC33: Invisible | AD33: Invisible | AE33: Editable | AF33: Invisible | AG33: Editable | AH33: Editable | AI33: Invisible
A34: 30 | B34: Presented Date | C34: Apttus_Proposal__Presented_Date__c | D34: Date | F34: Custom | L34: The date the quote/proposal was presented to the customer | N34: =VLOOKUP(B34,'Sheet 1'!$B$2:$C$108,2,FALSE) -> #N/A | O34: Editable | P34: Invisible | Q34: Invisible | R34: Editable | S34: Invisible | T34: Invisible | U34: Editable | V34: Editable | W34: Editable | X34: Editable | Y34: Editable | Z34: Editable | AA34: Editable | AB34: Editable | AC34: Invisible | AD34: Invisible | AE34: Editable | AF34: Invisible | AG34: Editable | AH34: Editable | AI34: Invisible
A35: 31 | B35: Preview | C35: Apttus_Proposal__Preview__c | D35: Formula (Text) | E35: 1300 | F35: Custom | I35: IF($User.UIThemeDisplayed == 'Theme4d',HYPERLINK("/one/one.app#/alohaRedirect/apex/Apttus_Proposal__ProposalGenerate?id="&Id & "&action=Preview", IMAGE("/resource/Apttus_Proposal__Button_Preview", "Preview"),"_self"),HYPERLINK("/apex/Apttus_Proposal__ProposalGenerate?id="&Id & "&action=Preview", IMAGE("/resource/Apttus_Proposal__Button_Preview", "Preview"),"_self")) | L35: Preview a quote/proposal | M35: Preview a quote/proposal | N35: =VLOOKUP(B35,'Sheet 1'!$B$2:$C$108,2,FALSE) -> V2 | O35: Read-Only | P35: Invisible | Q35: Invisible | R35: Editable | S35: Invisible | T35: Invisible | U35: Read-Only | V35: Editable | W35: Read-Only | X35: Read-Only | Y35: Editable | Z35: Editable | AA35: Editable | AB35: Editable | AC35: Invisible | AD35: Invisible | AE35: Editable | AF35: Invisible | AG35: Editable | AH35: Editable | AI35: Invisible
A36: 32 | B36: Primary Contact | C36: Apttus_Proposal__Primary_Contact__c | D36: Lookup (Contact) | F36: Custom | L36: The primary contact associated with the quote/proposal | N36: =VLOOKUP(B36,'Sheet 1'!$B$2:$C$108,2,FALSE) -> #N/A | O36: Editable | P36: Invisible | Q36: Invisible | R36: Editable | S36: Invisible | T36: Invisible | U36: Editable | V36: Editable | W36: Editable | X36: Editable | Y36: Editable | Z36: Editable | AA36: Editable | AB36: Editable | AC36: Invisible | AD36: Invisible | AE36: Editable | AF36: Invisible | AG36: Editable | AH36: Editable | AI36: Invisible
A37: 33 | B37: Primary | C37: Apttus_Proposal__Primary__c | D37: Checkbox | F37: Custom | K37: ✓ | L37: Indicates whether the quote/proposal is the primary quote to update the related opportunity | N37: =VLOOKUP(B37,'Sheet 1'!$B$2:$C$108,2,FALSE) -> V2 | O37: Editable | P37: Invisible | Q37: Invisible | R37: Editable | S37: Invisible | T37: Invisible | U37: Editable | V37: Editable | W37: Editable | X37: Editable | Y37: Editable | Z37: Editable | AA37: Editable | AB37: Editable | AC37: Invisible | AD37: Invisible | AE37: Editable | AF37: Invisible | AG37: Editable | AH37: Editable | AI37: Invisible
A38: 34 | B38: Proposal Approval Date | C38: Apttus_Proposal__Proposal_Approval_Date__c | D38: Date | F38: Custom | L38: The date the quote/proposal was approved | N38: =VLOOKUP(B38,'Sheet 1'!$B$2:$C$108,2,FALSE) -> #N/A | O38: Editable | P38: Invisible | Q38: Invisible | R38: Editable | S38: Invisible | T38: Invisible | U38: Editable | V38: Editable | W38: Editable | X38: Editable | Y38: Editable | Z38: Editable | AA38: Editable | AB38: Editable | AC38: Invisible | AD38: Invisible | AE38: Editable | AF38: Invisible | AG38: Editable | AH38: Editable | AI38: Invisible
A39: 35 | B39: Proposal Category | C39: Apttus_Proposal__Proposal_Category__c | D39: Picklist | F39: Custom | H39: Quote;Proposal | L39: The quote/proposal category | M39: The quote/proposal category | N39: =VLOOKUP(B39,'Sheet 1'!$B$2:$C$108,2,FALSE) -> #N/A | O39: Editable | P39: Invisible | Q39: Invisible | R39: Editable | S39: Invisible | T39: Invisible | U39: Editable | V39: Editable | W39: Editable | X39: Editable | Y39: Editable | Z39: Editable | AA39: Editable | AB39: Editable | AC39: Invisible | AD39: Invisible | AE39: Editable | AF39: Invisible | AG39: Editable | AH39: Editable | AI39: Invisible
A40: 36 | B40: Proposal Expiration Date | C40: Apttus_Proposal__Proposal_Expiration_Date__c | D40: Date | F40: Custom | L40: The quote/proposal expiration date | N40: =VLOOKUP(B40,'Sheet 1'!$B$2:$C$108,2,FALSE) -> #N/A | O40: Editable | P40: Invisible | Q40: Invisible | R40: Editable | S40: Invisible | T40: Invisible | U40: Editable | V40: Editable | W40: Editable | X40: Editable | Y40: Editable | Z40: Editable | AA40: Editable | AB40: Editable | AC40: Invisible | AD40: Invisible | AE40: Editable | AF40: Invisible | AG40: Editable | AH40: Editable | AI40: Invisible
...

Sheet RFP Layout
A1: Object | C1: Quote/Proposal | D1: Record Type | E1: RFP
A2: API Name | C2: Apttus_Proposal__Proposal__c | D2: Layout Name | E2: RFP Layout
A4: NO | B4: Label | C4: API Name | D4: Data Type | E4: Position | G4: Readonly | H4: Required | I4: Note
A5: Information (Header visible on edit only)
A6: 1 | B6: Proposal ID | C6: Name | D6: Text | E6: ✓ | G6: Readonly | I6: Required Field
A7: 2 | B7: Owner | C7: OwnerId | D7: Lookup (Group,User) | F7: ✓ | G7: Readonly | I7: Required Field
A8: 3 | B8: Proposal Name | C8: Apttus_Proposal__Proposal_Name__c | D8: Text | E8: ✓ | H8: Required
A9: 4 | B9: Record Type | C9: RecordTypeId | D9: Lookup (Record Type) | F9: ✓ | G9: Readonly
A10: 5 | B10: Opportunity | C10: Apttus_Proposal__Opportunity__c | D10: Lookup (Opportunity) | E10: ✓ | H10: Required
A11: 6 | B11: Account | C11: Apttus_Proposal__Account__c | D11: Lookup (Account) | F11: ✓
A12: 7 | B12: Description | C12: Apttus_Proposal__Description__c | D12: Long Text Area | E12: ✓
A13: 8 | B13: Account Cert Central ID | C13: APTS_CertCentral_Acct_ID__c | D13: Text | F13: ✓ | G13: Readonly
A14: 9 | B14: Special Terms | C14: Apttus_Proposal__Special_Terms__c | D14: Text Area | E14: ✓
A15: 10 | B15: Primary Contact | C15: Apttus_Proposal__Primary_Contact__c | D15: Lookup (Contact) | F15: ✓
A16: 11 | B16: Amount | C16: Apttus_Proposal__Amount__c | D16: Currency | E16: ✓ | G16: Readonly
A17: 12 | B17: Approval Stage | C17: Apttus_Proposal__Approval_Stage__c | D17: Picklist | F17: ✓ | G17: Readonly
A18: 13 | B18: Make Primary | C18: Apttus_Proposal__MakePrimary__c | D18: Text | E18: ✓ | G18: Readonly
A19: 14 | B19: Strategic Importance | C19: Apttus_Proposal__Strategic_Importance__c | D19: Picklist | F19: ✓
A20: 15 | B20: Bulk Purchase Amount | C20: APTS_Bulk_Purchase_Amount__c | D20: Currency | E20: ✓
A21: 16 | B21: Risk Factors | C21: Apttus_Proposal__Risk_Factors__c | D21: Picklist (Multi-Select) | F21: ✓
A22: 17 | B22: Billing Rule Changed | C22: APTS_Billing_Rule_Changed__c | D22: Checkbox | E22: ✓
A23: 18 | B23: Ready To Generate | C23: Apttus_Proposal__ReadyToGenerate__c | D23: Checkbox | F23: ✓
A24: 19 | B24: Quote Primary Contact | C24: APTS_Quote_Primary_Contact__c | D24: Lookup (Contact) | E24: ✓
A25: 20 | B25: Created By | C25: CreatedById | D25: Lookup (User) | F25: ✓ | G25: Readonly | I25: Required Field
A26: 21 | B26: Auto Renew | C26: APTS_Flat_Fee_Auto_Renew__c | D26: Checkbox | E26: ✓
A27: 22 | B27: Last Modified By | C27: LastModifiedById | D27: Lookup (User) | F27: ✓ | G27: Readonly | I27: Required Field
A28: 23 | B28: Additional CA Approval | C28: APTS_Additional_CA_Approval__c | D28: Checkbox | E28: ✓
A29: 24 | B29: DigiCert One ID | C29: DigiCert_One_ID__c | D29: Text | F29: ✓ | G29: Readonly
A30: 25 | B30: Partner Cert Central ID | C30: APTS_CertCentral_Partner_ID__c | D30: Text | E30: ✓ | G30: Readonly
A31: 26 | B31: Territory | C31: APTS_Territory__c | D31: Text | E31: ✓ | G31: Readonly
A32: 27 | B32: Hold-off Invoicing | C32: APTS_Hold_off_Invoicing__c | D32: Checkbox | E32: ✓
A33: 28 | B33: Tax Amount (Japan) | C33: Tax_Amount__c | D33: Number (18, 0) | E33: ✓ | G33: Readonly
A34: 29 | B34: Owner (Jap) | C34: Owner_Jap__c | D34: Text | E34: ✓ | G34: Readonly
A35: 30 | B35: Project MATTER | C35: APTS_Project_MATTER__c | D35: Checkbox | E35: ✓ | G35: Readonly
A36: RFP Dates
A37: 31 | B37: RFP Intake Date | C37: Apttus_Proposal__RFP_Intake_Date__c | D37: Date | E37: ✓
A38: 32 | B38: Internal Deadline | C38: Apttus_Proposal__Internal_Deadline__c | D38: Date | F38: ✓
A39: 33 | B39: RFP Response Due Date | C39: Apttus_Proposal__RFP_Response_Due_Date__c | D39: Date | E39: ✓
A40: 34 | B40: Presented Date | C40: Apttus_Proposal__Presented_Date__c | D40: Date | F40: ✓
A41: 35 | B41: Valid Until Date | C41: Apttus_Proposal__Valid_Until_Date__c | D41: Date | E41: ✓
...

Sheet RCA Quote - Fields
A1: Object | C1: Quote
A2: API Name | C2: Quote
I3: Conga Fields
A4: NO | B4: Field Label | C4: API Name | D4: Data Type | E4: Data Type | F4: Data Type | G4: Required | H4: Picklist Values | I4: Conga Field Label | J4: Field type | K4: Required | L4: Comments
A5: 1 | B5: Quote ID | C5: Id | D5: id | F5: Standard | G5: Required | I5: Record ID | J5: Standard | K5: Required
A6: 2 | B6: Owner ID | C6: OwnerId | D6: Lookup (Group,User) | F6: Standard | G6: Required | I6: Owner ID | J6: Standard | K6: Required
A7: 3 | B7: Deleted | C7: IsDeleted | D7: Checkbox | F7: Standard | I7: Deleted | J7: Standard
A8: 4 | B8: Quote Name | C8: Name | D8: Text | E8: 255 | F8: Standard | G8: Required | I8: Proposal Name | J8: Custom
A9: 5 | B9: Opportunity ID | C9: OpportunityId | D9: Master-Detail (Opportunity) | F9: Standard | I9: Opportunity | J9: Custom
A10: 6 | B10: Price Book ID | C10: Pricebook2Id | D10: Lookup (Price Book) | F10: Standard | I10: Price List | J10: Custom
A11: 7 | B11: Contact ID | C11: ContactId | D11: Lookup (Contact) | F11: Standard
A12: 8 | B12: Quote Number | C12: QuoteNumber | D12: Auto Number | E12: 30 | F12: Standard | G12: Required | I12: Proposal ID | J12: Standard | K12: Required
A13: 9 | B13: Syncing | C13: IsSyncing | D13: Checkbox | F13: Standard
A14: 10 | B14: Shipping and Handling | C14: ShippingHandling | D14: Currency | F14: Standard | I14: Shipping & Handling | J14: Custom
A15: 11 | B15: Tax | C15: Tax | D15: Currency | F15: Standard
A16: 12 | B16: Status | C16: Status | D16: Picklist | F16: Standard | H16: Draft;Needs Review;In Review;Approved;Rejected;Presented;Accepted;Denied | L16: Need to check if Apttus_QPApprov__Approval_Status__c / Apttus_Proposal__Approval_Stage__c fields from Conga can be considered
A17: 13 | B17: Expiration Date | C17: ExpirationDate | D17: Date | F17: Standard | I17: Proposal Expiration Date | J17: Custom
A18: 14 | B18: Description | C18: Description | D18: Long Text Area | E18: 32000 | F18: Standard | I18: Description | J18: Custom
A19: 15 | B19: Subtotal | C19: Subtotal | D19: Roll-Up Summary | F19: Standard
A20: 16 | B20: Total Price | C20: TotalPrice | D20: Roll-Up Summary | F20: Standard
A21: 17 | B21: Line Items | C21: LineItemCount | D21: Roll-Up Summary | F21: Standard
A22: 18 | B22: Bill To Street | C22: BillingStreet | D22: Text Area | E22: 255 | F22: Standard | L22: It will Auto Populate from BillTo Address
A23: 19 | B23: Bill To City | C23: BillingCity | D23: Text | E23: 40 | F23: Standard | L23: It will Auto Populate from BillTo Address
A24: 20 | B24: Bill To State/Province | C24: BillingState | D24: Text | E24: 80 | F24: Standard | L24: It will Auto Populate from BillTo Address
A25: 21 | B25: Bill To Zip/Postal Code | C25: BillingPostalCode | D25: Text | E25: 20 | F25: Standard | L25: It will Auto Populate from BillTo Address
A26: 22 | B26: Bill To Country | C26: BillingCountry | D26: Text | E26: 80 | F26: Standard | L26: It will Auto Populate from BillTo Address
A27: 23 | B27: Bill To Latitude | C27: BillingLatitude | D27: Number (3, 15) | E27: 18 | F27: Standard
A28: 24 | B28: Bill To Longitude | C28: BillingLongitude | D28: Number (3, 15) | E28: 18 | F28: Standard
A29: 25 | B29: Bill To Geocode Accuracy | C29: BillingGeocodeAccuracy | D29: Picklist | F29: Standard | H29: Address;NearAddress;Block;Street;ExtendedZip;Zip;Neighborhood;City;County;State;Unknown
A30: 26 | B30: Bill To | C30: BillingAddress | D30: Address | F30: Standard | I30: Bill To | J30: Custom
A31: 27 | B31: Ship To Street | C31: ShippingStreet | D31: Text Area | E31: 255 | F31: Standard | L31: It will Auto Populate from ShipTo Address
A32: 28 | B32: Ship To City | C32: ShippingCity | D32: Text | E32: 40 | F32: Standard | L32: It will Auto Populate from ShipTo Address
A33: 29 | B33: Ship To State/Province | C33: ShippingState | D33: Text | E33: 80 | F33: Standard | L33: It will Auto Populate from ShipTo Address
A34: 30 | B34: Ship To Zip/Postal Code | C34: ShippingPostalCode | D34: Text | E34: 20 | F34: Standard | L34: It will Auto Populate from ShipTo Address
A35: 31 | B35: Ship To Country | C35: ShippingCountry | D35: Text | E35: 80 | F35: Standard | L35: It will Auto Populate from ShipTo Address
A36: 32 | B36: Ship To Latitude | C36: ShippingLatitude | D36: Number (3, 15) | E36: 18 | F36: Standard
A37: 33 | B37: Ship To Longitude | C37: ShippingLongitude | D37: Number (3, 15) | E37: 18 | F37: Standard
A38: 34 | B38: Ship To Geocode Accuracy | C38: ShippingGeocodeAccuracy | D38: Picklist | F38: Standard | H38: Address;NearAddress;Block;Street;ExtendedZip;Zip;Neighborhood;City;County;State;Unknown
A39: 35 | B39: Ship To | C39: ShippingAddress | D39: Address | F39: Standard | I39: Ship To | J39: Custom
A40: 36 | B40: Quote To Street | C40: QuoteToStreet | D40: Text Area | E40: 255 | F40: Standard
...

Sheet As Is Quote Layout 
A1: # | B1: Label | C1: Data Type | D1: ReadOnly/Editable | E1: Forsys Comments | F1: Clarification | G1: Business Justification | H1: Source of population | I1: Comments
A2: Quote Details section
A3: 1 | B3: Proposal ID | C3: Text | D3: R | E3: It will be auto populated by system | H3: S
A4: 2 | B4: Owner | C4: Lookup (Group,User) | D4: E | E4: It will be auto populated by system but user can change the owner of the quote | F4: Up to which stage the ownership of the quote can be changed? | G4: [RB] No validation today | H4: S
A5: 3 | B5: Proposal Name | C5: Text | D5: E | E5: It will be auto populated by system but user can edit it | F5: How it needs to be defaulted? (For eg. Account _OppName ) | G5: [RB] I believe its just Opty name | H5: O
A6: 4 | B6: Quote Type | C6: Picklist | D6: E | E6: It will be auto populated by system based on the Opportunity type | F6: 1. Is there any mapping between Opportunity type, Opportunity Contract Type and Quote Type? 2. Based on which field from the Opportunity, Quote Type needs to be defaulted? | G6: [RB] No. Default is Standard | H6: S | I6: Getting populated from APTS_ProposalTrigger_Handler Apex class
A7: 5 | B7: Deal Type | C7: Picklist | D7: E | E7: It is user selection field | H7: U | I7: It is used in Approval Rules
A8: 6 | B8: Approval Stage | C8: Picklist | D8: R | E8: It will be auto populated by system and default value will be Draft. | H8: S | I8: Getting updated from APTS_ProposalTrigger_Handler and APTS_CancelProposalExtension Apex classes. If APTS_Revert_to_Presented__c field is reverted to true and Approval stage is accepted then the Approval stage gets updated to Presented in APTS_Proposal_Before_Save_Flow flow
A9: 7 | B9: Valid Until Date | C9: Date | D9: E | E9: It will be auto populated by system and default value will be current date + 60 days User can edit it. | F9: Are there any validations required to restrict the update of this field based on Quote stage? | G9: [RB] No validation today | H9: S | I9: Getting populated from APTS_Default_Start_Date_on_Proposal Flow | K9: S- System Populated Fields O- Fields coming from Opportunity D- Derived from flow or code U- User input fields A- Account related fields
A10: 8 | B10: Primary | C10: Checkbox | D10: R | E10: System will automatically mark it once the quote is Approved | F10: Is there any requirement to mark the first quote as Primary by default? | G10: [RB] Yes | H10: S | I10: Getting populated from APTS_MarkPrimaryAndSyncWithOpportunity Apex class where we are making it as true. We are marking Apttus_Proposal__Primary__c as false in APTS_CancelProposalExtension Apex class
A11: 9 | B11: Auto Renew | C11: Checkbox | D11: E | E11: It needs to be checked by user | F11: In which use cases user will mark this checkbox ? | G11: [RB] Couple of validation rules - restricted for Subscription. | H11: U | I11: It is used in Approval Rules
A12: 10 | B12: Revert to Presented | C12: Checkbox | D12: E | E12: It needs to be checked by user | F12: 1. In which use cases user will mark this checkbox ? 2. Is it still required in To be? | G12: [RB] When they want to revert from accepted. I didnt think this was required in To be. You may confirm. | H12: U
A13: 11 | B13: CPI Adjustment | C13: Checkbox | D13: R | E13: It will be set by system based on some criteria | F13: For what all use cases this field will set to True? | G13: [RB] Based on attribute configuration for Subscription | H13: D | I13: Getting populated from Set_CPI_Adjustment_Check_on_Proposal Flow
A14: 12 | B14: Template Type | C14: Picklist | D14: E | E14: Detailed Quote Template Short Quote Template It will be defaulted by system to Short Quote Template. | F14: 1. Are these values still valid in To Be? | G14: [RB] My guess is not - may need to confirm. | H14: U
A15: 13 | B15: Description | C15: Long Text Area | D15: E | E15: It is user input field | F15: 1.Is this field being referred in Quote Template? 2. What kind of description this field will contain? | G15: [RB] It was at one point, not sure if any of the templates still use it | H15: U
A16: 14 | B16: Contract Type | C16: Picklist | D16: R | E16: It will be auto populated by system based on the Opportunity contract type In RCA, it will be user input field | F16: Need the mapping between Opportunity Contract Type and Quote Contract Type | G16: [RB] Derived via Formula field | H16: D | I16: Getting populated from Set_Contract_Type_and_Template_selection_on_Quote_Proposal flow
A17: 15 | B17: Credit Reason | C17: Picklist | D17: E | E17: It is user selection field | H17: U
A18: 16 | B18: Template Selection | C18: Picklist | D18: E | E18: It is user selection field | H18: U
A19: 17 | B19: Credit Amount | C19: Currency | D19: R | E19: It will be auto populated by system | F19: 1. From where this field value needs to be pulled? | G19: [RB] In case of Entrust credit, I believe its pulled in upon cart finalization. For other credits, its user entered. | H19: D | I19: Getting populated from APTS_ProposalTrigger_Handler Apex class
A20: 18 | B20: Template Comments | C20: Long Text Area | D20: E | E20: It is user input field | H20: U
A21: 19 | B21: Approve Credit | C21: Checkbox | D21: R | E21: It will be auto populated by system | F21: 1. From where this field value needs to be pulled? | G21: [RB] Derived via Formula field | H21: D | I21: It is a formula field. IF(TEXT(APTS_Credit_Reason__c) = 'Entrust Credit' && ((NOT(ISNULL(APTS_Approved_Credit_Amount__c)) && NOT(ISNULL(APTS_CREDIT_AMOUNT__c)) && ROUND(APTS_CREDIT_AMOUNT__c,0) <= ROUND(APTS_Approved_Credit_Amount__c,0)) || (ISPICKVAL( Apttus_QPApprov__Approval_Status__c , 'Approved')) ),TRUE, IF(TEXT(APTS_Credit_Reason__c) = 'Entrust Credit' && ( (NOT(ISNULL(APTS_Approved_Credit_Amount__c)) && NOT(ISNULL(APTS_CREDIT_AMOUNT__c)) && ROUND(APTS_CREDIT_AMOUNT__c,0) > ROUND(APTS_Approved_Credit_Amount__c,0)) || (ISNULL(APTS_Approved_Credit_Amount__c) && NOT(ISNULL(APTS_CREDIT_AMOUNT__c)) ) ),FALSE, IF(/*TEXT(APTS_Credit_Reason__c) = 'Revocation Credit'*/NOT(ISBLANK(TEXT(APTS_Credit_Reason__c))) && NOT(ISPICKVAL(APTS_Credit_Reason__c,"Entrust Credit")) && ISPICKVAL( Apttus_QPApprov__Approval_Status__c , 'Approved'),TRUE,FALSE)))
A22: 20 | B22: Allow Multiple Agreements (OF & SFA) | C22: Checkbox | D22: E | E22: It needs to be checked by user | F22: For what all use cases this field will set to True? | G22: [RB] User entered when they want to create multiple agreements -just used for validation. If the agreement creation flow is changing, will it still be required? | H22: U
A23: 21 | B23: Disable Consumption Report View in CC | C23: Checkbox | D23: E | E23: It needs to be checked by user | F23: For what all use cases this field will set to True? | G23: [RB] When Partner Sales motion is sell-with and for Subscriotion contract | H23: U
A24: Account & Contact section
A25: 1 | B25: Opportunity | C25: Lookup (Opportunity) | D25: R | E25: It will be auto populated by system with the Opportuniy from which the Quote is created | H25: O
A26: 2 | B26: Quote Primary Contact | C26: Lookup (Contact) | D26: E | E26: It should be defaulted with the Account Contact from which the Opportunity is created. User can edit it | H26: O
A27: 3 | B27: Account | C27: Lookup (Account) | D27: R | E27: It will be auto populated by system with Opportunity Account | H27: O
A28: 4 | B28: Billing Contact | C28: Lookup (Contact) | E28: It is user input field. User can select the approriate contact from the Lookup | F28: Are there any restrictions for the Billing Contact that only specific Contacts should be displayed? | G28: [RB] Related contacts only | H28: U
A29: 5 | B29: Account Segment | C29: Text | D29: R | E29: It will be defaulted from the selected Account | H29: A
A30: 6 | B30: Account Payment Term | C30: Text | D30: R | E30: It will be defaulted from the selected Account | H30: A
A31: 7 | B31: Account Cert Central ID | C31: Text | D31: R | E31: It will be defaulted from the selected Account | H31: A
A32: 8 | B32: Payment Term | C32: Lookup (Payment Term) | D32: E | E32: It should be defaulted with the Account Payment Term but user can edit it | H32: A
A33: 9 | B33: Bill To Partner / Distributor | C33: Lookup (Account) | D33: E | E33: In case of Direct deal it should be selected as same Account and in case of Indirect deal it should be selected with Partner Account | F33: Are there any restrictions for selection of this field? | G33: [RB] Pulled from the opty, user entry not allowed CS: In current system it is editable field and only at quote level user is selecting the deal type. | H33: U
A34: 10 | B34: Contract Type (Existing) | C34: Text | D34: R | E34: It is a Formula field and pulling the value from Account | F34: Is this field driving any business logic? | G34: [RB] I believe it is in the Agreement stage to supersede existing contract | H34: A
A35: 11 | B35: Partner Cert Central ID | C35: Text | D35: R | E35: It should be defaulted from Partner Account | H35: A
A36: 12 | B36: Contract Start Date (Existing) | C36: Date | D36: R | E36: It is a Formula field and pulling the value from Account | F36: Is this field driving any business logic? | G36: [RB] I believe it is in the Agreement stage to supersede existing contract | H36: A
A37: 13 | B37: Partner Channel | C37: Text | D37: R | E37: It is a Formula field based on the Partner Sales Motion field value from the Opportunity | F37: What is the significance of this field and where it is being used? | G37: [RB] Informational only | H37: O
A38: 14 | B38: Contract End Date (Existing) | C38: Date | D38: R | E38: It is a Formula field and pulling the value from Account | F38: Is this field driving any business logic? | G38: [RB] I believe it is in the Agreement stage to supersede existing contract | H38: A
A39: 15 | B39: Marketplace Partner Account | C39: Lookup (Account) | D39: R | F39: with which Partner Account this field will be populated and what are the use cases where this Account is required? | G39: [RB] For marketplace Sell with deal
A40: 16 | B40: Support Level (Existing) | C40: Text | D40: R | E40: It is a Formula field and pulling the value from Account | H40: A
...

Sheet As Is Quote Backend fields
A1: NO | B1: Field Label | C1: API Name | D1: Data Type | E1: Field Type | F1: Is field Used ?? | G1: Forsys Comments
A2: 1 | B2: Record ID | C2: Id | D2: id | E2: Standard | F2: =VLOOKUP(C2,'Sheet 1'!$E$2:$F$92,2,FALSE) -> #N/A | G2: It can be replaced with standard RCA Quote Object field
A3: 2 | B3: Owner ID | C3: OwnerId | D3: Lookup (Group,User) | E3: Standard | F3: =VLOOKUP(C3,'Sheet 1'!$E$2:$F$92,2,FALSE) -> #N/A | G3: It can be replaced with standard RCA Quote Object field
A4: 3 | B4: Deleted | C4: IsDeleted | D4: Checkbox | E4: Standard | F4: =VLOOKUP(C4,'Sheet 1'!$E$2:$F$92,2,FALSE) -> #N/A | G4: It can be replaced with standard RCA Quote Object field
A5: 5 | B5: Currency ISO Code | C5: CurrencyIsoCode | D5: Picklist | E5: Standard | F5: =VLOOKUP(C5,'Sheet 1'!$E$2:$F$92,2,FALSE) -> #N/A
A6: 6 | B6: Record Type ID | C6: RecordTypeId | D6: Lookup (Record Type) | E6: Standard | F6: =VLOOKUP(C6,'Sheet 1'!$E$2:$F$92,2,FALSE) -> #N/A | G6: It can be replaced with standard RCA Quote Object field
A7: 7 | B7: Created Date | C7: CreatedDate | D7: Date/Time | E7: Standard | F7: =VLOOKUP(C7,'Sheet 1'!$E$2:$F$92,2,FALSE) -> #N/A | G7: It can be replaced with standard RCA Quote Object field
A8: 8 | B8: Created By ID | C8: CreatedById | D8: Lookup (User) | E8: Standard | F8: =VLOOKUP(C8,'Sheet 1'!$E$2:$F$92,2,FALSE) -> #N/A | G8: It can be replaced with standard RCA Quote Object field
A9: 9 | B9: Last Modified Date | C9: LastModifiedDate | D9: Date/Time | E9: Standard | F9: =VLOOKUP(C9,'Sheet 1'!$E$2:$F$92,2,FALSE) -> #N/A
A10: 10 | B10: Last Modified By ID | C10: LastModifiedById | D10: Lookup (User) | E10: Standard | F10: =VLOOKUP(C10,'Sheet 1'!$E$2:$F$92,2,FALSE) -> #N/A | G10: It can be replaced with standard RCA Quote Object field
A11: 11 | B11: System Modstamp | C11: SystemModstamp | D11: Date/Time | E11: Standard | F11: =VLOOKUP(C11,'Sheet 1'!$E$2:$F$92,2,FALSE) -> #N/A
A12: 12 | B12: Last Activity Date | C12: LastActivityDate | D12: Date | E12: Standard | F12: =VLOOKUP(C12,'Sheet 1'!$E$2:$F$92,2,FALSE) -> #N/A
A13: 13 | B13: Last Viewed Date | C13: LastViewedDate | D13: Date/Time | E13: Standard | F13: =VLOOKUP(C13,'Sheet 1'!$E$2:$F$92,2,FALSE) -> #N/A
A14: 14 | B14: Last Referenced Date | C14: LastReferencedDate | D14: Date/Time | E14: Standard | F14: =VLOOKUP(C14,'Sheet 1'!$E$2:$F$92,2,FALSE) -> #N/A
A15: 17 | B15: Create Agreement | C15: Apttus_Proposal__CreateAgreement__c | D15: Formula (Text) | E15: Custom | F15: =VLOOKUP(C15,'Sheet 1'!$E$2:$F$92,2,FALSE) -> #N/A | G15: Not Required in RCA
A16: 19 | B16: Discount % | C16: Apttus_Proposal__Discount_Percent__c | D16: Percent | E16: Custom | F16: =VLOOKUP(C16,'Sheet 1'!$E$2:$F$92,2,FALSE) -> not used
A17: 20 | B17: Expected End Date | C17: Apttus_Proposal__ExpectedEndDate__c | D17: Date | E17: Custom | F17: =VLOOKUP(C17,'Sheet 1'!$E$2:$F$92,2,FALSE) -> #N/A | G17: Used in apex:APTS_ProposalTrigger_Handler
A18: 22 | B18: Generate | C18: Apttus_Proposal__Generate__c | D18: Formula (Text) | E18: Custom | F18: =VLOOKUP(C18,'Sheet 1'!$E$2:$F$92,2,FALSE) -> #N/A | G18: Not Required in RCA
A19: 23 | B19: Grand Total | C19: Apttus_Proposal__Grand_Total__c | D19: Formula (Currency) | E19: Custom | F19: =VLOOKUP(C19,'Sheet 1'!$E$2:$F$92,2,FALSE) -> #N/A | G19: Do we have any standard field in RCA Quote object to capture the Quote Total?
A20: 24 | B20: Internal Deadline | C20: Apttus_Proposal__Internal_Deadline__c | D20: Date | E20: Custom | F20: =VLOOKUP(C20,'Sheet 1'!$E$2:$F$92,2,FALSE) -> not used
A21: 25 | B21: Make Primary | C21: Apttus_Proposal__MakePrimary__c | D21: Formula (Text) | E21: Custom | F21: =VLOOKUP(C21,'Sheet 1'!$E$2:$F$92,2,FALSE) -> #N/A | G21: It will be replaced with Start Sync action in RCA
A22: 26 | B22: Net Amount | C22: Apttus_Proposal__Net_Amount__c | D22: Formula (Currency) | E22: Custom | F22: =VLOOKUP(C22,'Sheet 1'!$E$2:$F$92,2,FALSE) -> #N/A | G22: Not Required in RCA
A23: 29 | B23: Present | C23: Apttus_Proposal__Present__c | D23: Formula (Text) | E23: Custom | F23: =VLOOKUP(C23,'Sheet 1'!$E$2:$F$92,2,FALSE) -> #N/A | G23: Not Required in RCA
A24: 30 | B24: Presented Date | C24: Apttus_Proposal__Presented_Date__c | D24: Date | E24: Custom | F24: =VLOOKUP(C24,'Sheet 1'!$E$2:$F$92,2,FALSE) -> #N/A | G24: No Reference
A25: 32 | B25: Primary Contact | C25: Apttus_Proposal__Primary_Contact__c | D25: Lookup (Contact) | E25: Custom | F25: =VLOOKUP(C25,'Sheet 1'!$E$2:$F$92,2,FALSE) -> #N/A
A26: 34 | B26: Proposal Approval Date | C26: Apttus_Proposal__Proposal_Approval_Date__c | D26: Date | E26: Custom | F26: =VLOOKUP(C26,'Sheet 1'!$E$2:$F$92,2,FALSE) -> not used
A27: 35 | B27: Proposal Category | C27: Apttus_Proposal__Proposal_Category__c | D27: Picklist | E27: Custom | F27: =VLOOKUP(C27,'Sheet 1'!$E$2:$F$92,2,FALSE) -> #N/A
A28: 36 | B28: Proposal Expiration Date | C28: Apttus_Proposal__Proposal_Expiration_Date__c | D28: Date | E28: Custom | F28: =VLOOKUP(C28,'Sheet 1'!$E$2:$F$92,2,FALSE) -> not used
A29: 38 | B29: RFP Intake Date | C29: Apttus_Proposal__RFP_Intake_Date__c | D29: Date | E29: Custom | F29: =VLOOKUP(C29,'Sheet 1'!$E$2:$F$92,2,FALSE) -> not used
A30: 39 | B30: RFP Response Due Date | C30: Apttus_Proposal__RFP_Response_Due_Date__c | D30: Date | E30: Custom | F30: =VLOOKUP(C30,'Sheet 1'!$E$2:$F$92,2,FALSE) -> not used
A31: 40 | B31: RFP Stage | C31: Apttus_Proposal__RFP_Stage__c | D31: Picklist | E31: Custom | F31: =VLOOKUP(C31,'Sheet 1'!$E$2:$F$92,2,FALSE) -> not used
A32: 41 | B32: RFP Value | C32: Apttus_Proposal__RFP_Value__c | D32: Currency | E32: Custom | F32: =VLOOKUP(C32,'Sheet 1'!$E$2:$F$92,2,FALSE) -> not used
A33: 42 | B33: Ready To Generate | C33: Apttus_Proposal__ReadyToGenerate__c | D33: Checkbox | E33: Custom | F33: =VLOOKUP(C33,'Sheet 1'!$E$2:$F$92,2,FALSE) -> #N/A
A34: 43 | B34: Ready To Present | C34: Apttus_Proposal__ReadyToPresent__c | D34: Checkbox | E34: Custom | F34: =VLOOKUP(C34,'Sheet 1'!$E$2:$F$92,2,FALSE) -> #N/A
A35: 44 | B35: Related Quote/Proposal | C35: Apttus_Proposal__RelatedProposalId__c | D35: Lookup (Quote/Proposal) | E35: Custom | F35: =VLOOKUP(C35,'Sheet 1'!$E$2:$F$92,2,FALSE) -> not used
A36: 45 | B36: Request Approval | C36: Apttus_Proposal__Request_Approval__c | D36: Formula (Text) | E36: Custom | F36: =VLOOKUP(C36,'Sheet 1'!$E$2:$F$92,2,FALSE) -> #N/A | G36: Not Required in RCA
A37: 46 | B37: Risk Factors | C37: Apttus_Proposal__Risk_Factors__c | D37: Picklist (Multi-Select) | E37: Custom | F37: =VLOOKUP(C37,'Sheet 1'!$E$2:$F$92,2,FALSE) -> not used
A38: 47 | B38: Sales Tax Amount | C38: Apttus_Proposal__Sales_Tax_Amount__c | D38: Formula (Currency) | E38: Custom | F38: =VLOOKUP(C38,'Sheet 1'!$E$2:$F$92,2,FALSE) -> #N/A | G38: Not Required in RCA
A39: 48 | B39: Sales Tax % | C39: Apttus_Proposal__Sales_Tax_Percent__c | D39: Percent | E39: Custom | F39: =VLOOKUP(C39,'Sheet 1'!$E$2:$F$92,2,FALSE) -> not used
A40: 49 | B40: Send Proposal | C40: Apttus_Proposal__SendProposal__c | D40: Formula (Text) | E40: Custom | F40: =VLOOKUP(C40,'Sheet 1'!$E$2:$F$92,2,FALSE) -> #N/A | G40: Not Required in RCA
...

Sheet Product Configuration-Analysis
A1: Field Label | B1: API Name | C1: Data Type | D1: Comments (Line Item Obj) | E1: Apex Classes | F1: Flow | G1: Custom Field (On Product Configuration Object) 1 | H1: Custom Field (On Product Configuration Object) 2 | I1: Custom Field (On Line Item Object) 1 | J1: Custom Field (On Line Item Object) 2 | K1: Custom Field (On Product Attribute Value) 1
A2: Record ID | B2: Id | C2: id
A3: Owner ID | B3: OwnerId | C3: Lookup (Group,User)
A4: Deleted | B4: IsDeleted | C4: Checkbox
A5: Configuration Name | B5: Name | C5: Text
A6: Currency ISO Code | B6: CurrencyIsoCode | C6: Picklist
A7: Created Date | B7: CreatedDate | C7: Date/Time
A8: Created By ID | B8: CreatedById | C8: Lookup (User)
A9: Last Modified Date | B9: LastModifiedDate | C9: Date/Time
A10: Last Modified By ID | B10: LastModifiedById | C10: Lookup (User)
A11: System Modstamp | B11: SystemModstamp | C11: Date/Time
A12: Last Activity Date | B12: LastActivityDate | C12: Date
A13: Sold To | B13: Apttus_Config2__AccountId__c | C13: Lookup (Account)
... A37: Intent | B37: Apttus_Config2__Intent__c | C37: Picklist
A38: Is Price Pending | B38: Apttus_Config2__IsPricePending__c | C38: Checkbox | D38: The field is referenced only in a Flow | F38: Product Configuration Before Save Handler
A39: Is Task Pending | B39: Apttus_Config2__IsTaskPending__c | C39: Checkbox
A40: Is Transient | B40: Apttus_Config2__IsTransient__c | C40: Checkbox
A41: Is Validation Pending | B41: Apttus_Config2__IsValidationPending__c | C41: Checkbox
A42: Legal Entity | B42: Apttus_Config2__LegalEntityId__c | C42: Lookup (Legal Entity)
A43: Line Items Awaiting Price | B43: Apttus_Config2__LineItemsAwaitingPrice__c | C43: Text
A44: Location | B44: Apttus_Config2__LocationId__c | C44: Lookup (Account Location)
A45: Order | B45: Apttus_Config2__OrderId__c | C45: Lookup (Apttus Order)
A46: Parent Configuration | B46: Apttus_Config2__ParentConfigurationId__c | C46: Lookup (Product Configuration)
A47: Payment Term | B47: Apttus_Config2__PaymentTermId__c | C47: Lookup (Payment Term)
A48: Price List | B48: Apttus_Config2__PriceListId__c | C48: Lookup (Price List)
A49: Primordial | B49: Apttus_Config2__PrimordialId__c | C49: Lookup (Product Configuration)
A50: Purchase Identifier | B50: Apttus_Config2__PurchaseId__c | C50: Text
... A53: Ship To | B53: Apttus_Config2__ShipToAccountId__c | C53: Lookup (Account)
A54: Status | B54: Apttus_Config2__Status__c | C54: Picklist | D54: The field is referenced only in a Flow and Apex class | E54: APTS_ELACalculatorLaunchController, APTS_ProposalTrigger_Handler, APTS_ValidationCallback, APTS_ValidationCallbackTest, APTS_RampLineNumberBatchTest, APTS_AnnualSummaryUpdate_Batch, APTS_AnnualSummaryUpdate_BatchTest, APTS_ValidationCallbackTestNew | F54: Populate Quote/Proposal fields after finalization, Proposal Line Item Before Save Flow
A55: Summary Group Type | B55: Apttus_Config2__SummaryGroupType__c | C55: Picklist
A56: Use Type | B56: Apttus_Config2__UseType__c | C56: Picklist
A57: Version Number | B57: Apttus_Config2__VersionNumber__c | C57: Number (4, 0) | D57: The field is referenced only in a Apex class | E57: APTS_ProposalTrigger_Handler
A58: Base Relation Count | B58: Apttus_Config2__BaseRelationCount__c | C58: Roll-Up Summary
A59: Number Of Items | B59: Apttus_Config2__NumberOfItems__c | C59: Roll-Up Summary
A60: Quote/Proposal | B60: Apttus_QPConfig__Proposald__c | C60: Lookup (Quote/Proposal)
A61: Agreement | B61: Apttus_CMConfig__AgreementId__c | C61: Lookup (Agreement)
A62: Approval Preview Status | B62: Apttus_CQApprov__Approval_Preview_Status__c | C62: Picklist
A63: Approval Status | B63: Apttus_CQApprov__Approval_Status__c | C63: Picklist
A64: Business Object Reference | B64: Apttus_CQApprov__BusinessObjectRefId__c | C64: Text
A65: Line Item Approval Status | B65: Apttus_CQApprov__LineItem_Approval_Status__c | C65: Picklist
...

Sheet To Be Quote Fields Layout
B1: Label | C1: Data Type | D1: ReadOnly/Editable | E1: Conga API | F1: RCA API | G1: RCA Label | H1: RCA Data Type | I1: Standard/Custom | J1: Layout field | K1: Comments | O1: Created or not | Q1: Approvals applicable field
A2: Quote Details section
A3: 1 | B3: Proposal ID | C3: Auto Number | D3: R | E3: Name | F3: QuoteNumber | G3: Quote Number | H3: Auto Number | I3: S | J3: Y
A4: 2 | B4: Owner | C4: Lookup (Group,User) | D4: E | E4: OwnerId | F4: OwnerId | G4: Owner ID | H4: Lookup (Group,User) | I4: S | J4: Y
A5: 3 | B5: Proposal Name | C5: Text | D5: E | E5: Apttus_Proposal__Proposal_Name__c | F5: Name | G5: Quote Name | H5: Text | I5: S | J5: Y
A6: 4 | B6: Quote Type | C6: Picklist | D6: E | E6: APTS_Quote_Type__c | F6: RCA_Quote_Type__c | G6: Quote Type | H6: Picklist | I6: C | J6: Y
A7: 5 | B7: Deal Type | C7: Picklist | D7: E | E7: APTS_Deal_Type__c | F7: RCA_Deal_Type__c | I7: C | J7: Y | Q7: Yes
A8: 6 | B8: Approval Stage | C8: Picklist | D8: R | E8: Apttus_Proposal__Approval_Stage__c | F8: Status | G8: Status | H8: Picklist | I8: S | J8: Y
A9: 7 | B9: Valid Until Date | C9: Date | D9: E | E9: Apttus_Proposal__Valid_Until_Date__c | G9: Expiration Date | H9: Date | I9: S | J9: Y
A10: 8 | B10: Primary | C10: Checkbox | D10: R | E10: Apttus_Proposal__Primary__c | G10: IsSyncing | H10: Checkbox | I10: S | J10: Y
A11: 9 | B11: Auto Renew | C11: Checkbox | D11: E | E11: APTS_Flat_Fee_Auto_Renew__c | F11: RCA_Flat_Fee_Auto_Renew__c | I11: C | J11: Y
A12: 10 | B12: Revert to Presented | D12: E | E12: APTS_Revert_to_Presented__c | K12: Not Required
A13: 11 | B13: CPI Adjustment | C13: Checkbox | D13: R | E13: APTS_CPI_Adjustment__c | F13: RCA_CPI_Adjustment__c | I13: C | J13: Y
A14: 12 | B14: Template Type | C14: Picklist | D14: E | E14: APTS_Template_Type__c | F14: RCA_Template_Type__c | G14: Template Type | H14: Picklist | J14: Y | K14: Do we need this field in To Be? (Pavan/Karthik)
A15: 13 | B15: Description | C15: Long Text Area | D15: E | E15: Apttus_Proposal__Description__c | I15: ? | J15: Y | K15: Do we need this field in To Be? (Pavan/Karthik)
A16: 14 | B16: Contract Type | C16: Picklist | D16: R | E16: APTS_Contract_Type_Values__c | F16: RCA_Contract_Type_Values__c | G16: Contract Type | H16: Picklist | I16: C | J16: Y
A17: 15 | B17: Credit Reason | C17: Picklist | D17: E | E17: APTS_Credit_Reason__c | F17: RCA_Credit_Reason__c | G17: Credit Reason | H17: Picklist | I17: C | J17: Y
A18: 16 | B18: Template Selection | C18: Picklist | D18: E | E18: APTS_Template_Selection__c | I18: ? | J18: Y | K18: Do we need this field in To Be? (Pavan/Karthik)
A19: 17 | B19: Credit Amount | C19: Currency | D19: R | E19: APTS_CREDIT_AMOUNT__c | F19: RCA_CREDIT_AMOUNT__c | G19: Credit Amount | H19: Currency | I19: C | J19: Y
A20: 18 | B20: Template Comments | C20: Long Text Area | D20: E | E20: APTS_Template_Comments__c | F20: RCA_Template_Comments__c | G20: Template Comments | H20: Long Text Area | I20: C | J20: Y
A21: 19 | B21: Approve Credit | C21: Formula (Checkbox) | D21: R | E21: APTS_APPLY_CREDIT__c | F21: RCA_APPLY_CREDIT__c | G21: Approve Credit | H21: Formula (Checkbox) | I21: C | J21: Y
A22: 20 | B22: Allow Multiple Agreements (OF & SFA) | C22: Checkbox | D22: E | E22: APTS_Multiple_Agreements_required__c | F22: RCA_Multiple_Agreements_required__c | G22: Allow Multiple Agreements (OF & SFA) | H22: Checkbox | I22: C | J22: Y
A23: 21 | B23: Disable Consumption Report View in CC | C23: Checkbox | D23: E | E23: APTS_DisableConsumptionReportViewinCertC__c | F23: RCA_DisableConsumptionReportViewinCertC__c | G23: Disable Consumption Report View in CC | H23: Checkbox | I23: C | J23: Y
A24: Account & Contact section (Need to rename as "Account, Contact & Address Information")
A25: 1 | B25: Opportunity | C25: Lookup (Opportunity) | D25: R | E25: Apttus_Proposal__Opportunity__c | G25: Opportunity ID | H25: Master-Detail (Opportunity) | I25: S | J25: Y
A26: 2 | B26: Quote Primary Contact | C26: Lookup (Contact) | D26: E | E26: APTS_Quote_Primary_Contact__c | F26: RCA_Quote_Primary_Contact__c | G26: Contact ID | H26: Lookup (Contact) | I26: S | J26: Y
A27: 3 | B27: Copy Primary Contact Address | C27: Checkbox | D27: E | E27: APTS_Copy_Primary_Contact_Address__c | I27: C | J27: Y | K27: Moved from Order to Quote
A28: 4 | B28: Account | C28: Lookup (Account) | D28: R | E28: Apttus_Proposal__Account__c | G28: Account ID | H28: Lookup (Account) | I28: S | J28: Y
A29: 5 | B29: Account Segment | C29: Formula (Text) | D29: R | E29: Account_Segment__c | F29: RCA__Account_Segment__c | I29: C | J29: Y
A30: 6 | B30: Account Payment Term | C30: Formula (Text) | D30: R | E30: APTS_Account_Payment_Term__c | F30: RCA_Account_Payment_Term__c | I30: C | J30: Y
A31: 7 | B31: Account Cert Central ID | C31: Formula (Text) | D31: R | E31: APTS_CertCentral_Acct_ID__c | F31: RCA_CertCentral_Acct_ID__c | I31: C | J31: Y
A32: 8 | B32: Payment Term | C32: Lookup (Payment Term) | D32: E | E32: Apttus_QPConfig__PaymentTermId__c | J32: Y
A33: 9 | B33: Bill To Partner / Distributor | C33: Lookup (Account) | D33: E | E33: APTS_Deal_Registration_Partner__c | F33: RCA_Deal_Registration_Partner__c | G33: Partner Account ID | H33: Lookup (Account) | I33: S | J33: Y
A34: 10 | B34: Partner Cert Central ID | C34: Formula (Text) | D34: R | E34: APTS_CertCentral_Partner_ID__c | F34: RCA_Partner_Cert_Central_ID__c | I34: C | J34: Y
A35: 11 | B35: Partner Channel | C35: Formula (Text) | D35: R | E35: APTS_Partner_Channel__c | F35: RCA_Partner_Channel__c | I35: C | J35: Y
A36: 12 | B36: Contract Type (Existing) | C36: Formula (Text) | D36: R | E36: APTS_Contract_Type_Existing__c | F36: RCA_Contract_Type_Existing__c | I36: C | J36: Y
A37: 13 | B37: Contract Start Date (Existing) | C37: Formula (Date) | D37: R | E37: APTS_Contract_Start_Date_Existing__c | F37: RCA_Contract_Start_Date_Existing__c | I37: C | J37: Y
A38: 14 | B38: Contract End Date (Existing) | C38: Formula (Date) | D38: R | E38: APTS_Contract_End_Date_Existing__c | F38: RCA_Contract_End_Date_Existing__c | I38: C | J38: Y
A39: 15 | B39: Marketplace Partner Account | C39: Lookup (Account) | D39: R | E39: APTS_MarketplacePartnerAccount__c | F39: RCA_MarketplacePartnerAccount__c | I39: C | J39: Y
A40: 16 | B40: Support Level (Existing) | C40: Formula (Text) | D40: R | E40: APTS_Support_Level_Account__c | F40: RCA_Support_Level_Account__c | I40: C | J40: Y
...

Sheet Sheet 1
A1: Quote Proposal | B1: Layout V2
A2: Record ID | B2: Proposal ID | C2: V2 | E2: Apttus_Proposal__Discount_Percent__c | F2: not used
A3: Owner ID | B3: Owner | C3: V2 | E3: Apttus_Proposal__Internal_Deadline__c | F3: not used
A4: Deleted | B4: Proposal Name | C4: V2 | E4: Apttus_Proposal__Proposal_Approval_Date__c | F4: not used
A5: Proposal ID | B5: Quote Type | C5: V2 | E5: Apttus_Proposal__Proposal_Expiration_Date__c | F5: not used
A6: Currency ISO Code | B6: Deal Type | C6: V2 | E6: Apttus_Proposal__RFP_Intake_Date__c | F6: not used
A7: Record Type ID | B7: Approval Stage | C7: V2 | E7: Apttus_Proposal__RFP_Response_Due_Date__c | F7: not used
