Workbook

Sheet Sheet1
A1: _ | B1: Id | C1: ExternalId | D1: RCA_ExternalId__c | E1: Type
A2: [Product2] | B2: 01tWC00000AYBXxYAP | C2: 01t4z000008h0NLAAY
A3: [Product2] | B3: 01tWC00000AYBXyYAP | C3: 01t4z000008iBW3AAM
A4: [Product2] | B4: 01tWC00000AYBXzYAP | C4: 01t4z000008iBW4AAM
A5: [Product2] | B5: 01tWC00000AYBY1YAP | C5: 01t4z000008jjfJAAQ
A6: [Product2] | B6: 01tWC00000AYBY2YAP | C6: 01t0z000007f40zAAA
A7: [Product2] | B7: 01tWC00000AYBY3YAP | C7: 01t0z000007f410AAA
A8: [Product2] | B8: 01tWC00000AYBY4YAP | C8: 01t0z000007f411AAA
A9: [Product2] | B9: 01tWC00000AYBY5YAP | C9: 01t0z000007f412AAA
A10: [Product2] | B10: 01tWC00000AYBY6YAP | C10: 01t0z000007f413AAA
A11: [Product2] | B11: 01tWC00000AYBY7YAP | C11: 01t0z000007f414AAA
A12: [Product2] | B12: 01tWC00000AYBY8YAP | C12: 01t0z000007f415AAA
A13: [Product2] | B13: 01tWC00000AYBY9YAP | C13: 01t0z000007f416AAA
... A428: [Product2] | B428: 01tWC00000BLkDVYA1 | C428: 01tVu000000UDcZIAW

Sheet Sheet8
A1: _ | B1: Id | C1: CreatedDate | D1: Type | E1: Name | F1: LastModifiedDate | G1: IsActive | H1: ExternalId
A2: [Product2] | B2: 01tdp000009QOCnAAO | C2: 2025-12-16T01:48:46.000+0000 | D2: Bundle | E2: CertCentral Subscription (Annual Commit) | F2: 2025-12-16T01:48:46.000+0000 | G2: TRUE
A3: [Product2] | B3: 01tdp000009QL0QAAW | C3: 2025-12-16T01:18:53.000+0000 | D3: Bundle | E3: CertCentral Bulk Dollar | F3: 2025-12-16T01:18:53.000+0000 | G3: TRUE
A4: [Product2] | B4: 01tdp000009QN3pAAG | C4: 2025-12-16T01:18:37.000+0000 | D4: Bundle | E4: CertCentral Bulk Units | F4: 2025-12-16T01:18:37.000+0000 | G4: TRUE
A5: [Product2] | B5: 01tdp000009QN3qAAG | C5: 2025-12-16T01:18:37.000+0000 | D5: Bundle | E5: CertCentral PerCert | F5: 2025-12-16T01:18:37.000+0000 | G5: TRUE
A6: [Product2] | B6: 01tdp000009H4gPAAS | C6: 2025-12-09T03:54:57.000+0000 | E6: DigiCert Trust Lifecycle Manager - Organizational Certificate Private Root Creation and Maintenance | F6: 2025-12-09T03:54:57.000+0000 | G6: TRUE
A7: [Product2] | B7: 01tdp000009H4gQAAS | C7: 2025-12-09T03:54:57.000+0000 | E7: DigiCert Trust Lifecycle Manager - Private Code Signing Certificates Private Root Creation and Maintenance | F7: 2025-12-09T03:54:57.000+0000 | G7: TRUE
A8: [Product2] | B8: 01tdp000009H4gLAAS | C8: 2025-12-09T03:54:57.000+0000 | E8: DIGICERT PKI PLATFORM - WEB GATEWAY INSPECTION - 12 MONTHS Private Root Creation and Maintenance | F8: 2025-12-09T03:54:57.000+0000 | G8: TRUE
A9: [Product2] | B9: 01tdp000009H4gSAAS | C9: 2025-12-09T03:54:57.000+0000 | E9: DigiCert Trust Lifecycle Manager - User Seat Private Root Creation and Maintenance | F9: 2025-12-09T03:54:57.000+0000 | G9: TRUE
A10: [Product2] | B10: 01tdp000009H4gTAAS | C10: 2025-12-09T03:54:57.000+0000 | E10: DigiCert Trust Lifecycle Manager - Web Gateway Inspection Private Root Creation and Maintenance | F10: 2025-12-09T03:54:57.000+0000 | G10: TRUE
A11: [Product2] | B11: 01tdp000009H4gRAAS | C11: 2025-12-09T03:54:57.000+0000 | E11: DigiCert Trust Lifecycle Manager - Private Server Seat Private Root Creation and Maintenance | F11: 2025-12-09T03:54:57.000+0000 | G11: TRUE
A12: [Product2] | B12: 01tdp000009H4gMAAS | C12: 2025-12-09T03:54:57.000+0000 | E12: DigiCert Software Trust Manager - Code Signing Account Creation and Maintenance | F12: 2025-12-09T03:54:57.000+0000 | G12: TRUE
A13: [Product2] | B13: 01tdp000009H4gNAAS | C13: 2025-12-09T03:54:57.000+0000 | E13: DigiCert Software Trust Manager - Threat Detection Account Creation and Maintenance | F13: 2025-12-09T03:54:57.000+0000 | G13: TRUE
A14: [Product2] | B14: 01tdp000009H4gOAAS | C14: 2025-12-09T03:54:57.000+0000 | E14: DigiCert Trust Lifecycle Manager - Device Seat Private Root Creation and Maintenance | F14: 2025-12-09T03:54:57.000+0000 | G14: TRUE
A15: [Product2] | B15: 01tdp000009H4ekAAC | C15: 2025-12-09T03:54:56.000+0000 | E15: Digicert Device Trust Manager - Essentials Private Root Creation and Maintenance | F15: 2025-12-09T03:54:56.000+0000 | G15: TRUE
A16: [Product2] | B16: 01tdp000009H4ejAAC | C16: 2025-12-09T03:54:56.000+0000 | E16: Digicert Device Trust Manager - Advanced Private Root Creation and Maintenance | F16: 2025-12-09T03:54:56.000+0000 | G16: TRUE
A17: [Product2] | B17: 01tdp000009H4emAAC | C17: 2025-12-09T03:54:56.000+0000 | E17: DIGICERT DOCUMENT TRUST MANAGER FOR ORGANIZATIONS - 12 MONTHS Account Creation and Maintenance | F17: 2025-12-09T03:54:56.000+0000 | G17: TRUE
... A27: [Product2] | B27: 01tdp000009H4elAAC | C27: 2025-12-09T03:54:56.000+0000 | E27: DIGICERT DOCUMENT TRUST MANAGER FOR INDIVIDUALS - 12 MONTHS Account Creation and Maintenance | F27: 2025-12-09T03:54:56.000+0000 | G27: TRUE
A28: [Product2] | B28: 01tdp000009H4DLAA0 | C28: 2025-12-09T03:41:13.000+0000 | D28: Bundle | E28: ELA (C2000) – Semi-Annual Billing | F28: 2025-12-09T03:41:13.000+0000 | G28: TRUE
A29: [Product2] | B29: 01tdp000009H4DJAA0 | C29: 2025-12-09T03:41:13.000+0000 | D29: Bundle | E29: Flat Fee | F29: 2025-12-09T03:41:13.000+0000 | G29: TRUE
A30: [Product2] | B30: 01tdp000009H4DKAA0 | C30: 2025-12-09T03:41:13.000+0000 | D30: Bundle | E30: ELA (C2000) - Annual Billing | F30: 2025-12-09T03:41:13.000+0000 | G30: TRUE
A31: [Product2] | B31: 01tdp000009H4DMAA0 | C31: 2025-12-09T03:41:13.000+0000 | D31: Bundle | E31: ELA (C2000) - Quarterly Billing | F31: 2025-12-09T03:41:13.000+0000 | G31: TRUE
A32: [Product2] | B32: 01tdp000009GN6qAAG | C32: 2025-12-08T20:45:02.000+0000 | E32: Ascertia Level 2 support 24x7x365 | F32: 2025-12-15T17:29:23.000+0000 | G32: FALSE
A33: [Product2] | B33: 01tdp000009GN6pAAG | C33: 2025-12-08T20:45:02.000+0000 | E33: Ascertia Installation guidance via Basecamp | F33: 2025-12-15T17:29:23.000+0000 | G33: FALSE
A34: [Product2] | B34: 01tdp000009GN6oAAG | C34: 2025-12-08T20:45:02.000+0000 | E34: Ascertia SigningHub rebranded mobile app | F34: 2025-12-15T17:29:23.000+0000 | G34: FALSE
A35: [Product2] | B35: 01tdp000009GN6kAAG | C35: 2025-12-08T20:45:02.000+0000 | E35: DIGICERT DOCUMENT TRUST MANAGER ADDITIONAL SIGNINGS | F35: 2025-12-15T17:29:23.000+0000 | G35: FALSE
A36: [Product2] | B36: 01tdp000009GN5VAAW | C36: 2025-12-08T20:45:02.000+0000 | E36: DIGICERT DOCUMENT TRUST MANAGER FOR INDIVIDUALS - 12 MONTHS | F36: 2025-12-15T17:29:23.000+0000 | G36: FALSE
A37: [Product2] | B37: 01tdp000009GN5OAAW | C37: 2025-12-08T20:45:02.000+0000 | E37: DigiCert GSMA v2 - DS (1 cert: Authentication) | F37: 2025-12-15T17:29:23.000+0000 | G37: FALSE
A38: [Product2] | B38: 01tdp000009GN5JAAW | C38: 2025-12-08T20:45:02.000+0000 | E38: Ascertia ADSS SAM Appliance - Annual Support | F38: 2025-12-15T17:29:23.000+0000 | G38: FALSE
A39: [Product2] | B39: 01tdp000009GN5IAAW | C39: 2025-12-08T20:45:02.000+0000 | E39: Ascertia ADSS SAM Appliance - Hardware | F39: 2025-12-15T17:29:23.000+0000 | G39: FALSE
A40: [Product2] | B40: 01tdp000009GN5EAAW | C40: 2025-12-08T20:45:02.000+0000 | E40: 3rd Party Hardware Offerings | F40: 2025-12-15T17:29:23.000+0000 | G40: FALSE
A41: [Product2] | B41: 01tdp000009GN5BAAW | C41: 2025-12-08T20:45:02.000+0000 | E41: 3rd Party Offerings | F41: 2025-12-15T17:29:23.000+0000 | G41: FALSE
A42: [Product2] | B42: 01tdp000009GN3rAAG | C42: 2025-12-08T20:45:01.000+0000 | E42: Thales DPoD | F42: 2025-12-15T17:29:23.000+0000 | G42: FALSE
A43: [Product2] | B43: 01tdp000009GN3jAAG | C43: 2025-12-08T20:45:01.000+0000 | E43: DigiCert Additional CA | F43: 2025-12-15T17:29:23.000+0000 | G43: FALSE
... A46: [Product2] | B46: 01tdp000009GMxLAAW | C46: 2025-12-08T20:45:00.000+0000 | E46: Private Root CA Creation and Maintenance | F46: 2025-12-15T17:29:23.000+0000 | G46: FALSE
A47: [Product2] | B47: 01tdp000009GMxJAAW | C47: 2025-12-08T20:45:00.000+0000 | D47: Bundle | E47: Subscription Services - In Active [Do Not Use] | F47: 2025-12-16T01:30:24.000+0000 | G47: FALSE
A48: [Product2] | B48: 01tdp000009GMxIAAW | C48: 2025-12-08T20:45:00.000+0000 | E48: Common Mark Certificate | F48: 2025-12-15T17:29:23.000+0000 | G48: FALSE
A49: [Product2] | B49: 01tdp000009GMxBAAW | C49: 2025-12-08T20:45:00.000+0000 | E49: EU Qualified Website Authentication Certificate (QWAC) PSD2 | F49: 2025-12-15T17:29:23.000+0000 | G49: FALSE
A50: [Product2] | B50: 01tdp000009GMx7AAG | C50: 2025-12-08T20:45:00.000+0000 | E50: Digicert Business Support | F50: 2025-12-15T17:29:23.000+0000 | G50: FALSE
A51: [Product2] | B51: 01tdp000009GMu7AAG | C51: 2025-12-08T20:44:57.000+0000 | E51: Premium (Class 2 S/MIME) | F51: 2025-12-15T17:29:23.000+0000 | G51: FALSE
...

Sheet Sheet4
A1: _ | B1: Id | C1: Name | D1: ExternalId | E1: RCA_ExternalId__c
A2: [Product2] | B2: 01t0z000006tlRPAAY | C2: DIGICERT PKI PLATFORM (GEMALTO) USB AUTHENTICATOR E5110 PLUS NO PIN 3YR WARRANTY | D2: 01t0z000006tlRPAAY | E2: 01t0z000006tlRPAAY
A3: [Product2] | B3: 01t0z00000753eyAAA | C3: DIGICERT NON-FEDERAL SSP PKI 7.5 ADDITIONAL PRIVATE CA | D3: 01t0z00000753eyAAA | E3: 01t0z00000753eyAAA
A4: [Product2] | B4: 01t0z00000753f0AAA | C4: DIGICERT NON-FEDERAL SSP PKI 7.5 CO-BRANDED SEATS | D4: 01t0z00000753f0AAA | E4: 01t0z00000753f0AAA
A5: [Product2] | B5: 01t0z00000753kPAAQ | C5: DIGICERT PKI PLATFORM 7.5 PRIVATE SEATS | D5: 01t0z00000753kPAAQ | E5: 01t0z00000753kPAAQ
A6: [Product2] | B6: 01t0z000007548oAAA | C6: DIGICERT FEDERAL SSP PKI 7.5 CO-BRANDED SEATS | D6: 01t0z000007548oAAA | E6: 01t0z000007548oAAA
A7: [Product2] | B7: 01t0z00000754KzAAI | C7: DIGICERT PKI PLATFORM 7.5 USER SEATS | D7: 01t0z00000754KzAAI | E7: 01t0z00000754KzAAI
A8: [Product2] | B8: 01t0z00000754QkAAI | C8: DIGICERT FEDERAL SSP PKI 7.5 ADDITIONAL PRIVATE CA | D8: 01t0z00000754QkAAI | E8: 01t0z00000754QkAAI
A9: [Product2] | B9: 01t0z00000755CYAAY | C9: DIGICERT PKI PLATFORM - PLATINUM SUPPORT - 12 MONTHS | D9: 01t0z00000755CYAAY | E9: 01t0z00000755CYAAY
A10: [Product2] | B10: 01t0z0000076pLFAAY | C10: DIGICERT ADDITIONAL CA | D10: 01t0z0000076pLFAAY | E10: 01t0z0000076pLFAAY
A11: [Product2] | B11: 01t0z0000076pM7AAI | C11: DIGICERT PKI PLATFORM FOR SMARTPHONE FENICS MONTHLY FEE FOR CERTIFICATE | D11: 01t0z0000076pM7AAI | E11: 01t0z0000076pM7AAI
A12: [Product2] | B12: 01t0z0000076pPeAAI | C12: DIGICERT PKI PLATFORM AA MODULE FEE | D12: 01t0z0000076pPeAAI | E12: 01t0z0000076pPeAAI
... A428: [Product2] | B428: 01tVu00000NtnndIAB | C428: DigiCert MSP Hub | D428: 01tVu00000NtnndIAB | E428: 01tVu00000NtnndIAB

Sheet Sheet5
A1: _ | B1: Id | C1: Name | D1: ExternalId
A2: [Product2] | B2: 01tWC00000AYBXxYAP | C2: Grid Robot Name | D2: 01t4z000008h0NLAAY | E2: {=XLOOKUP(D:D, Sheet4!B:B,Sheet4!C:C, "Name", 0)} -> Grid Robot Name
A3: [Product2] | B3: 01tWC00000AYBXyYAP | C3: Verified Mark Certificate FQDN Price | D3: 01t4z000008iBW3AAM | E3: {=XLOOKUP(D:D, Sheet4!B:B,Sheet4!C:C, "Name", 0)} -> Verified Mark Certificate FQDN Price
A4: [Product2] | B4: 01tWC00000AYBXzYAP | C4: Verified Mark Certificate | D4: 01t4z000008iBW4AAM | E4: {=XLOOKUP(D:D, Sheet4!B:B,Sheet4!C:C, "Name", 0)} -> Verified Mark Certificate
A5: [Product2] | B5: 01tWC00000AYBY1YAP | C5: Code Signing (Units) | D5: 01t4z000008jjfJAAQ | E5: {=XLOOKUP(D:D, Sheet4!B:B,Sheet4!C:C, "Name", 0)} -> Code Signing (Units)
A6: [Product2] | B6: 01tWC00000AYBY2YAP | C6: Authentication Only | D6: 01t0z000007f40zAAA | E6: {=XLOOKUP(D:D, Sheet4!B:B,Sheet4!C:C, "Name", 0)} -> Authentication Only
A7: [Product2] | B7: 01tWC00000AYBY3YAP | C7: Authentication Only - Non-Repudiation | D7: 01t0z000007f410AAA | E7: {=XLOOKUP(D:D, Sheet4!B:B,Sheet4!C:C, "Name", 0)} -> Authentication Only - Non-Repudiation
A8: [Product2] | B8: 01tWC00000AYBY4YAP | C8: Authentication Plus | D8: 01t0z000007f411AAA | E8: {=XLOOKUP(D:D, Sheet4!B:B,Sheet4!C:C, "Name", 0)} -> Authentication Plus
A9: [Product2] | B9: 01tWC00000AYBY5YAP | C9: Authentication Plus (AD Integration) | D9: 01t0z000007f412AAA | E9: {=XLOOKUP(D:D, Sheet4!B:B,Sheet4!C:C, "Name", 0)} -> Authentication Plus (AD Integration)
A10: [Product2] | B10: 01tWC00000AYBY6YAP | C10: Basic EV | D10: 01t0z000007f413AAA | E10: {=XLOOKUP(D:D, Sheet4!B:B,Sheet4!C:C, "Name", 0)} -> Basic EV
A11: [Product2] | B11: 01tWC00000AYBY7YAP | C11: Basic EV FQDN SAN | D11: 01t0z000007f414AAA | E11: {=XLOOKUP(D:D, Sheet4!B:B,Sheet4!C:C, "Name", 0)} -> Basic EV FQDN SAN
A12: [Product2] | B12: 01tWC00000AYBY8YAP | C12: Basic OV | D12: 01t0z000007f415AAA | E12: {=XLOOKUP(D:D, Sheet4!B:B,Sheet4!C:C, "Name", 0)} -> Basic OV
A13: [Product2] | B13: 01tWC00000AYBY9YAP | C13: Basic OV FQDN SAN | D13: 01t0z000007f416AAA | E13: {=XLOOKUP(D:D, Sheet4!B:B,Sheet4!C:C, "Name", 0)} -> Basic OV FQDN SAN
... A428: [Product2] | B428: 01tWC00000BLkDVYA1 | C428: Dedicated offline root HSM – Cancellation Fee | D428: 01tVu000000UDcZIAW | E428: {=XLOOKUP(D:D, Sheet4!B:B,Sheet4!C:C, "Name", 0)} -> Dedicated offline root HSM – Cancellation Fee

Sheet Delete from DCFull
A1: _ | B1: Id | C1: _CreatedDate | D1: _LastModifiedDate | E1: _ | F1: _RCA_ExternalId__c | G1: _Type | H1: __Status | I1: __Id | J1: __Action | K1: __Errors
A2: [Product2] | B2: 01tdp000009GMUIAA4 | C2: 2025-12-08T20:37:43.000+0000 | D2: 2025-12-08T20:37:43.000+0000 | F2: 01tWC00000AYBa0YAH | H2: Succeeded | I2: 01tdp000009GMUIAA4 | J2: Deleted
A3: [Product2] | B3: 01tdp000009GMxDAAW | C3: 2025-12-08T20:45:00.000+0000 | D3: 2025-12-08T20:45:00.000+0000 | F3: 01tWC00000AYBa1YAH | H3: Succeeded | I3: 01tdp000009GMxDAAW | J3: Deleted
A4: [Product2] | B4: 01tdp000009GMUJAA4 | C4: 2025-12-08T20:37:43.000+0000 | D4: 2025-12-08T20:37:43.000+0000 | F4: 01tWC00000AYBa2YAH | H4: Succeeded | I4: 01tdp000009GMUJAA4 | J4: Deleted
A5: [Product2] | B5: 01tdp000009GMUKAA4 | C5: 2025-12-08T20:37:43.000+0000 | D5: 2025-12-08T20:37:43.000+0000 | F5: 01tWC00000AYBa3YAH | H5: Succeeded | I5: 01tdp000009GMUKAA4 | J5: Deleted
A6: [Product2] | B6: 01tdp000009GMxEAAW | C6: 2025-12-08T20:45:00.000+0000 | D6: 2025-12-08T20:45:00.000+0000 | F6: 01tWC00000AYBa4YAH | H6: Succeeded | I6: 01tdp000009GMxEAAW | J6: Deleted
A7: [Product2] | B7: 01tdp000009GMxFAAW | C7: 2025-12-08T20:45:00.000+0000 | D7: 2025-12-08T20:45:00.000+0000 | F7: 01tWC00000AYBa5YAH | H7: Succeeded | I7: 01tdp000009GMxFAAW | J7: Deleted
A8: [Product2] | B8: 01tdp000009GMxGAAW | C8: 2025-12-08T20:45:00.000+0000 | D8: 2025-12-08T20:45:00.000+0000 | F8: 01tWC00000AYBa6YAH | H8: Succeeded | I8: 01tdp000009GMxGAAW | J8: Deleted
A9: [Product2] | B9: 01tdp000009GMULAA4 | C9: 2025-12-08T20:37:43.000+0000 | D9: 2025-12-08T20:37:43.000+0000 | F9: 01tWC00000AYBa7YAH | H9: Succeeded | I9: 01tdp000009GMULAA4 | J9: Deleted
A10: [Product2] | B10: 01tdp000009GMUMAA4 | C10: 2025-12-08T20:37:43.000+0000 | D10: 2025-12-08T20:37:43.000+0000 | F10: 01tWC00000AYBa8YAH | H10: Succeeded | I10: 01tdp000009GMUMAA4 | J10: Deleted
A11: [Product2] | B11: 01tdp000009GMUNAA4 | C11: 2025-12-08T20:37:43.000+0000 | D11: 2025-12-08T20:37:43.000+0000 | F11: 01tWC00000AYBa9YAH | H11: Succeeded | I11: 01tdp000009GMUNAA4 | J11: Deleted
A12: [Product2] | B12: 01tdp000009GMxHAAW | C12: 2025-12-08T20:45:00.000+0000 | D12: 2025-12-08T20:45:00.000+0000 | F12: 01tWC00000AYBaAYAX | H12: Succeeded | I12: 01tdp000009GMxHAAW | J12: Deleted
A13: [Product2] | B13: 01tdp000009GMxIAAW | C13: 2025-12-08T20:45:00.000+0000 | D13: 2025-12-08T20:45:00.000+0000 | F13: 01tWC00000AYBaBYAX | H13: Failed | I13: 01tdp000009GMxIAAW | K13: DELETE_FAILED: Your attempt to delete Common Mark Certificate could not be completed because it is associated with the following quote line items.: Test_Quote-4 []
A14: [Product2] | B14: 01tdp000009GMxKAAW | C14: 2025-12-08T20:45:00.000+0000 | D14: 2025-12-08T20:45:00.000+0000 | F14: 01tWC00000AYBaDYAX | H14: Succeeded | I14: 01tdp000009GMxKAAW | J14: Deleted
A15: [Product2] | B15: 01tdp000009GMxLAAW | C15: 2025-12-08T20:45:00.000+0000 | D15: 2025-12-08T20:45:00.000+0000 | F15: 01tWC00000AYBaEYAX | H15: Failed | I15: 01tdp000009GMxLAAW | K15: DELETE_FAILED: Your attempt to delete Private Root CA Creation and Maintenance could not be completed because it is associated with the following quote line items.: Test_Quote-4 []
A16: [Product2] | B16: 01tdp000009GMxMAAW | C16: 2025-12-08T20:45:00.000+0000 | D16: 2025-12-08T20:45:00.000+0000 | F16: 01tWC00000AYBaFYAX | H16: Succeeded | I16: 01tdp000009GMxMAAW | J16: Deleted
A17: [Product2] | B17: 01tdp000009GMxNAAW | C17: 2025-12-08T20:45:00.000+0000 | D17: 2025-12-08T20:45:00.000+0000 | F17: 01tWC00000AYBaGYAX | H17: Succeeded | I17: 01tdp000009GMxNAAW | J17: Deleted
A18: [Product2] | B18: 01tdp000009GMxOAAW | C18: 2025-12-08T20:45:00.000+0000 | D18: 2025-12-08T20:45:00.000+0000 | F18: 01tWC00000AYBaHYAX | H18: Succeeded | I18: 01tdp000009GMxOAAW | J18: Deleted
A19: [Product2] | B19: 01tdp000009GMUOAA4 | C19: 2025-12-08T20:37:43.000+0000 | D19: 2025-12-08T20:37:43.000+0000 | F19: 01tWC00000AYBaIYAX | H19: Failed | I19: 01tdp000009GMUOAA4 | K19: DELETE_FAILED: Your attempt to delete DigiCert KeyLocker could not be completed because it is associated with the following quote line items.: Test_Quote-4 []
A20: [Product2] | B20: 01tdp000009GMUPAA4 | C20: 2025-12-08T20:37:43.000+0000 | D20: 2025-12-08T20:37:43.000+0000 | F20: 01tWC00000AYBaJYAX | H20: Failed | I20: 01tdp000009GMUPAA4 | K20: DELETE_FAILED: Your attempt to delete Digicert Business Plus Support could not be completed because it is associated with the following asset action sources.: AAS-000000007 Your attempt to delete Digicert Business Plus Support could not be completed because it is associated with the following opportunity products.: New Logo - 2026 - 3 Day Blinds - Your attempt to delete Digicert Business Plus Support could not be completed because it is associated with the following order products.: 0000000009 Your attempt to delete Digicert Business Plus Support could not be completed because it is associated with the following quote line items.: Test Quote, Test_Quote_1, Test, Test_Quote_3 []
A21: [Product2] | B21: 01tdp000009GMxPAAW | C21: 2025-12-08T20:45:00.000+0000 | D21: 2025-12-08T20:45:00.000+0000 | F21: 01tWC00000AYBaKYAX | H21: Succeeded | I21: 01tdp000009GMxPAAW | J21: Deleted
A22: [Product2] | B22: 01tdp000009GMxQAAW | C22: 2025-12-08T20:45:00.000+0000 | D22: 2025-12-08T20:45:00.000+0000 | F22: 01tWC00000AYBaLYAX | H22: Succeeded | I22: 01tdp000009GMxQAAW | J22: Deleted
A23: [Product2] | B23: 01tdp000009GMVdAAO | C23: 2025-12-08T20:37:44.000+0000 | D23: 2025-12-08T20:37:44.000+0000 | F23: 01tWC00000AYBaMYAX | H23: Succeeded | I23: 01tdp000009GMVdAAO | J23: Deleted
A24: [Product2] | B24: 01tdp000009GMxRAAW | C24: 2025-12-08T20:45:00.000+0000 | D24: 2025-12-08T20:45:00.000+0000 | F24: 01tWC00000AYBaNYAX | H24: Succeeded | I24: 01tdp000009GMxRAAW | J24: Deleted
A25: [Product2] | B25: 01tdp000009GMVeAAO | C25: 2025-12-08T20:37:44.000+0000 | D25: 2025-12-08T20:37:44.000+0000 | F25: 01tWC00000AYBaOYAX | H25: Succeeded | I25: 01tdp000009GMVeAAO | J25: Deleted
A26: [Product2] | B26: 01tdp000009GMVfAAO | C26: 2025-12-08T20:37:44.000+0000 | D26: 2025-12-08T20:37:44.000+0000 | F26: 01tWC00000AYBaPYAX | H26: Succeeded | I26: 01tdp000009GMVfAAO | J26: Deleted
A27: [Product2] | B27: 01tdp000009GMyfAAG | C27: 2025-12-08T20:45:00.000+0000 | D27: 2025-12-08T20:45:00.000+0000 | F27: 01tWC00000AYBaQYAX | H27: Succeeded | I27: 01tdp000009GMyfAAG | J27: Deleted
A28: [Product2] | B28: 01tdp000009GMQnAAO | C28: 2025-12-08T20:37:41.000+0000 | D28: 2025-12-08T20:37:41.000+0000 | F28: 01tWC00000AYBXxYAP | H28: Succeeded | I28: 01tdp000009GMQnAAO | J28: Deleted
A29: [Product2] | B29: 01tdp000009GMQoAAO | C29: 2025-12-08T20:37:41.000+0000 | D29: 2025-12-08T20:37:41.000+0000 | F29: 01tWC00000AYBXyYAP | H29: Succeeded | I29: 01tdp000009GMQoAAO | J29: Deleted
A30: [Product2] | B30: 01tdp000009GMQpAAO | C30: 2025-12-08T20:37:41.000+0000 | D30: 2025-12-08T20:37:41.000+0000 | F30: 01tWC00000AYBXzYAP | H30: Succeeded | I30: 01tdp000009GMQpAAO | J30: Deleted
A31: [Product2] | B31: 01tdp000009GMQqAAO | C31: 2025-12-08T20:37:41.000+0000 | D31: 2025-12-08T20:37:41.000+0000 | F31: 01tWC00000AYBY1YAP | H31: Succeeded | I31: 01tdp000009GMQqAAO | J31: Deleted
A32: [Product2] | B32: 01tdp000009GMtqAAG | C32: 2025-12-08T20:44:57.000+0000 | D32: 2025-12-08T20:44:57.000+0000 | F32: 01tWC00000AYBY2YAP | H32: Succeeded | I32: 01tdp000009GMtqAAG | J32: Deleted
... A76: [Product2] | B76: 01tdp000009GMvVAAW | C76: 2025-12-08T20:44:59.000+0000 | D76: 2025-12-08T20:44:59.000+0000 | F76: 01tWC00000AYBYsYAP | H76: Succeeded | I76: 01tdp000009GMvVAAW | J76: Deleted
A77: [Product2] | B77: 01tdp000009GMu7AAG | C77: 2025-12-08T20:44:57.000+0000 | D77: 2025-12-08T20:44:57.000+0000 | F77: 01tWC00000AYBYTYA5 | H77: Failed | I77: 01tdp000009GMu7AAG | K77: DELETE_FAILED: Your attempt to delete Premium (Class 2 S/MIME) could not be completed because it is associated with the following opportunity products.: New Logo - 2026 - AdForce Advertising Agency - Your attempt to delete Premium (Class 2 S/MIME) could not be completed because it is associated with the following quote line items.: Sanity_QA []
A78: [Product2] | B78: 01tdp000009GMSSAA4 | C78: 2025-12-08T20:37:42.000+0000 | D78: 2025-12-08T20:37:42.000+0000 | F78: 01tWC00000AYBYtYAP | H78: Succeeded | I78: 01tdp000009GMSSAA4 | J78: Deleted
A79: [Product2] | B79: 01tdp000009GMR1AAO | C79: 2025-12-08T20:37:41.000+0000 | D79: 2025-12-08T20:37:41.000+0000 | F79: 01tWC00000AYBYUYA5 | H79: Succeeded | I79: 01tdp000009GMR1AAO | J79: Deleted
A80: [Product2] | B80: 01tdp000009GMvWAAW | C80: 2025-12-08T20:44:59.000+0000 | D80: 2025-12-08T20:44:59.000+0000 | F80: 01tWC00000AYBYuYAP | H80: Succeeded | I80: 01tdp000009GMvWAAW | J80: Deleted
A81: [Product2] | B81: 01tdp000009GMu8AAG | C81: 2025-12-08T20:44:57.000+0000 | D81: 2025-12-08T20:44:57.000+0000 | F81: 01tWC00000AYBYVYA5 | H81: Succeeded | I81: 01tdp000009GMu8AAG | J81: Deleted
A82: [Product2] | B82: 01tdp000009GMvXAAW | C82: 2025-12-08T20:44:59.000+0000 | D82: 2025-12-08T20:44:59.000+0000 | F82: 01tWC00000AYBYvYAP | H82: Succeeded | I82: 01tdp000009GMvXAAW | J82: Deleted
A83: [Product2] | B83: 01tdp000009GMR2AAO | C83: 2025-12-08T20:37:41.000+0000 | D83: 2025-12-08T20:37:41.000+0000 | F83: 01tWC00000AYBYWYA5 | H83: Succeeded | I83: 01tdp000009GMR2AAO | J83: Deleted
...

Sheet Inactivated
A1: _ | B1: Id | C1: Name | D1: CreatedDate | E1: LastModifiedDate | F1: IsActive
A2: [Product2] | B2: 01tdp000009GMSlAAO | C2: Dedicated Public CA Creation and Maintenance | D2: 2025-12-08T20:37:42.000+0000 | E2: 2025-12-08T20:37:42.000+0000 | F2: FALSE
A3: [Product2] | B3: 01tdp000009GMU9AAO | C3: Digicert Premium Support | D3: 2025-12-08T20:37:43.000+0000 | E3: 2025-12-08T20:37:43.000+0000 | F3: FALSE
A4: [Product2] | B4: 01tdp000009GMUDAA4 | C4: EU Electronic Seal | D4: 2025-12-08T20:37:43.000+0000 | E4: 2025-12-08T20:37:43.000+0000 | F4: FALSE
A5: [Product2] | B5: 01tdp000009GMUEAA4 | C5: EU Electronic Seal PSD2 | D5: 2025-12-08T20:37:43.000+0000 | E5: 2025-12-08T20:37:43.000+0000 | F5: FALSE
A6: [Product2] | B6: 01tdp000009GMUFAA4 | C6: EU Individual | D6: 2025-12-08T20:37:43.000+0000 | E6: 2025-12-08T20:37:43.000+0000 | F6: FALSE
A7: [Product2] | B7: 01tdp000009GMUOAA4 | C7: DigiCert KeyLocker | D7: 2025-12-08T20:37:43.000+0000 | E7: 2025-12-08T20:37:43.000+0000 | F7: FALSE
A8: [Product2] | B8: 01tdp000009GMUPAA4 | C8: Digicert Business Plus Support | D8: 2025-12-08T20:37:43.000+0000 | E8: 2025-12-08T20:37:43.000+0000 | F8: FALSE
A9: [Product2] | B9: 01tdp000009GMXSAA4 | C9: Ascertia Signature Unit Pack | D9: 2025-12-08T20:37:45.000+0000 | E9: 2025-12-08T20:37:45.000+0000 | F9: FALSE
A10: [Product2] | B10: 01tdp000009GMZ0AAO | C10: DigiCert MSP Hub | D10: 2025-12-08T20:37:45.000+0000 | E10: 2025-12-08T20:37:45.000+0000 | F10: FALSE
A11: [Product2] | B11: 01tdp000009GMaVAAW | C11: 3rd Party Professional Services Offerings | D11: 2025-12-08T20:37:45.000+0000 | E11: 2025-12-08T20:37:45.000+0000 | F11: FALSE
A12: [Product2] | B12: 01tdp000009GMamAAG | C12: Ascertia Service License | D12: 2025-12-08T20:37:45.000+0000 | E12: 2025-12-08T20:37:45.000+0000 | F12: FALSE
A13: [Product2] | B13: 01tdp000009GMu7AAG | C13: Premium (Class 2 S/MIME) | D13: 2025-12-08T20:44:57.000+0000 | E13: 2025-12-08T20:44:57.000+0000 | F13: FALSE
... A31: [Product2] | B31: 01tdp000009GN6qAAG | C31: Ascertia Level 2 support 24x7x365 | D31: 2025-12-08T20:45:02.000+0000 | E31: 2025-12-08T20:45:02.000+0000 | F31: FALSE

Sheet Dev - Product2
A1: _ | B1: Name | C1: ProductCode | D1: Description | E1: IsActive | F1: Family | G1: CurrencyIsoCode | H1: RecordTypeId | I1: ExternalDataSourceId | J1: Id | K1: RCA_ExternalId__c | L1: ExternalId | M1: DisplayUrl | N1: QuantityUnitOfMeasure | O1: StockKeepingUnit | P1: Type | Q1: AvailabilityDate | R1: DiscontinuedDate | S1: BasedOnId | T1: EndOfLifeDate | U1: HelpText | V1: IsAssetizable | W1: ConfigureDuringSale | X1: IsSoldOnlyWithOtherProds | Y1: SpecificationType | Z1: CanRamp | AA1: UsageModelType | AB1: Product_Type__c | AC1: GLOBAL_SPECIALIZATION__c | AD1: Internal_Peak__c | AE1: Oracle_Product_Code__c | AF1: Part_Number__c | AG1: Product_Category__c | AH1: Product_Family_Description__c | AI1: Product_Information__c | AJ1: Product_Subcategory__c | AK1: Quotable_Flag__c | AL1: SYMC_CreatedByID__c | AM1: SYMC_LastModifiedByID__c | AN1: Apttus_Config2__BundleInvoiceLevel__c | AO1: Zproduct_Id__c | AP1: Offering_Type__c | AQ1: Admin_Area_ID__c | AR1: Apttus_Config2__RenewalLeadTime__c | AS1: Category_L__c | AT1: Cost__c | AU1: FA_product_line__c | AV1: Genkaritsu__c | AW1: Hanbai_Keitai__c | AX1: Num_Hanbai__c | AY1: Product_Bunrui__c | AZ1: Public_Private__c | BA1: US_Report_Category__c | BB1: activedate_from__c | BC1: activedate_to__c | BD1: category_M__c | BE1: category_s__c | BF1: defered_term__c | BG1: delete_flags__c | BH1: ebs_account__c | BI1: ebs_business_unit__c | BJ1: ebs_business_unit_description__c | BK1: ebs_customer_order_enabled_flag__c | BL1: ebs_customer_order_flag__c | BM1: ebs_description__c | BN1: ebs_enabled_flag__c | BO1: ebs_invoice_enabled_flag__c | BP1: ebs_invoiceable_item_flag__c | BQ1: ebs_item_id__c | BR1: ebs_item_num__c | BS1: ebs_item_type__c | BT1: ebs_language__c | BU1: ebs_language_description__c | BV1: ebs_master_description__c | BW1: ebs_organization_id__c | BX1: ebs_product_line__c | BY1: ebs_product_line_description__c | BZ1: ebs_product_name__c | CA1: ebs_tax_code__c | CB1: ebs_unit_of_issue__c | CC1: kame_product_id__c | CD1: product_flag__c | CE1: revenue_type_id__c | CF1: servicelist__c | CG1: APTS_Apttus_Product__c | CH1: APTS_Cert_Category__c | CI1: APTS_Console__c | CJ1: APTS_Contract_Consumption_Method__c | CK1: APTS_Ext_ID__c | CL1: APTS_Is_Amendable__c | CM1: APTS_Is_Renewable__c | CN1: APTS_New_CPQ_CertCentral__c | CO1: APTS_Order__c | CP1: APTS_Product_Id_18__c | CQ1: APTS_Product_Line__c | CR1: APTS_Requires_CPF_Doc__c | CS1: APTS_Target_Channel__c | CT1: Type_QV__c | CU1: APTS_Config_Schema__c | CV1: APTS_Exclude_from_Ramping_Validation__c | CW1: ebs_invoicing_rule_id__c | CX1: APTS_Exclude_From_Channel_Discounts__c | CY1: APTS_True_Up_Product__c | CZ1: APTS_Japanese_Product_Name__c | DA1: Non_Recurring_Checkbox__c | DB1: Non_Future_Contracted__c | DC1: cc_product_api_id__c | DD1: APTS_Product_Category__c | DE1: APTS_Product_Line_L2__c | DF1: APTS_Product_Organisation_L1__c | DG1: APTS_Product_category_L3__c | DH1: APTS_Attributes_To_Consider_SKU__c | DI1: APTS_Do_not_consider_for_SKU_Code__c | DJ1: APTS_no_of_attributes_SKU__c | DK1: APTS_Level1_Abbrv__c | DL1: APTS_Level_2_Abbrv__c | DM1: APTS_Level_3_Abbrv__c | DN1: APTS_Product_Code_with_SKU__c | DO1: APTS_SKU_Code__c | DP1: Product_Category_SFDC__c | DQ1: APTS_Is_MSP_Quotable__c | DR1: Charge_Type__c | DS1: Is_Manual__c | DT1: Overage_Rate__c | DU1: Product_Alias__c | DV1: Product_Group__c | DW1: Unit__c | DX1: Charge_Model__c | DY1: ProductGroup__c | DZ1: RCA_Lifecycle_Status__c
A2: [Product2] | B2: Grid Robot Name | C2: Grid Robot Name | E2: TRUE | F2: DigiCert | G2: USD | H2: 012dp000005zfL7AAI | J2: 01t4z000008h0NLAAY | K2: 01t4z000008h0NLAAY | L2: 01t4z000008h0NLAAY | S2: 11BWC000002WLZ42AO | V2: TRUE | X2: TRUE | Y2: Commercial | Z2: FALSE | BG2: FALSE | CD2: FALSE | CG2: FALSE | CL2: FALSE | CM2: FALSE | CN2: FALSE | CP2: 01tWC00000AYBXxYAP | CR2: FALSE | CV2: FALSE | CX2: FALSE | CY2: FALSE | DA2: FALSE | DB2: FALSE | DI2: FALSE | DN2: Grid Robot Name | DQ2: FALSE | DS2: FALSE | DU2: Grid Robot Name | DY2: All SSL Product Grp | DZ2: Active
A3: [Product2] | B3: Verified Mark Certificate FQDN Price | C3: 99 | E3: TRUE | F3: DigiCert | G3: USD | H3: 012dp000005zfL7AAI | J3: 01t4z000008iBW3AAM | K3: 01t4z000008iBW3AAM | L3: 01t4z000008iBW3AAM | S3: 11BWC000002cka92AA | V3: TRUE | X3: TRUE | Y3: Commercial | Z3: FALSE | BG3: FALSE | CD3: FALSE | CG3: FALSE | CL3: FALSE | CM3: FALSE | CN3: FALSE | CP3: 01tWC00000AYBXyYAP | CR3: FALSE | CV3: FALSE | CX3: FALSE | CY3: FALSE | DA3: FALSE | DB3: FALSE | DI3: FALSE | DN3: 99 | DQ3: FALSE | DS3: FALSE | DU3: Verified Mark Certificate FQDN Price | DY3: All SSL Product Grp | DZ3: Active
A4: [Product2] | B4: Verified Mark Certificate | C4: 99-san | E4: TRUE | F4: DigiCert | G4: USD | H4: 012dp000005zfL7AAI | J4: 01t4z000008iBW4AAM | K4: 01t4z000008iBW4AAM | L4: 01t4z000008iBW4AAM | V4: TRUE | X4: TRUE | Y4: Commercial | Z4: FALSE | BG4: FALSE | CD4: FALSE | CG4: FALSE | CL4: FALSE | CM4: FALSE | CN4: FALSE | CP4: 01tWC00000AYBXzYAP | CR4: FALSE | CV4: FALSE | CX4: FALSE | CY4: FALSE | DA4: FALSE | DB4: FALSE | DI4: FALSE | DN4: 99-san | DQ4: FALSE | DS4: FALSE | DU4: Verified Mark Certificate | DZ4: Active
A5: [Product2] | B5: Code Signing (Units) | C5: Code Signing (Units) | E5: TRUE | F5: DigiCert | G5: USD | H5: 012dp000005zfL7AAI | J5: 01t4z000008jjfJAAQ | K5: 01t4z000008jjfJAAQ | L5: 01t4z000008jjfJAAQ | V5: TRUE | W5: Allowed | X5: TRUE | Y5: Commercial | Z5: FALSE | BG5: FALSE | CD5: FALSE | CG5: FALSE | CL5: FALSE | CM5: FALSE | CN5: FALSE | CP5: 01tWC00000AYBY1YAP | CR5: FALSE | CV5: FALSE | CX5: FALSE | CY5: FALSE | DA5: FALSE | DB5: FALSE | DI5: FALSE | DN5: Code Signing (Units) | DQ5: FALSE | DS5: FALSE | DU5: Code Signing (Units) | DZ5: Active
A6: [Product2] | B6: Authentication Only | C6: Authentication Only | E6: TRUE | F6: DigiCert | G6: USD | H6: 012dp000005zfL7AAI | J6: 01t0z000007f40zAAA | K6: 01t0z000007f40zAAA | L6: 01t0z000007f40zAAA | S6: 11BWC000002WLhn2AG | V6: TRUE | W6: Allowed | X6: TRUE | Y6: Commercial | Z6: FALSE | BG6: FALSE | CD6: FALSE | CG6: FALSE | CL6: FALSE | CM6: FALSE | CN6: FALSE | CP6: 01tWC00000AYBY2YAP | CR6: FALSE | CV6: FALSE | CX6: FALSE | CY6: FALSE | DA6: FALSE | DB6: FALSE | DI6: FALSE | DN6: Authentication Only | DQ6: FALSE | DS6: FALSE | DU6: Authentication Only | DZ6: Active
A7: [Product2] | B7: Authentication Only - Non-Repudiation | C7: Authentication Only - Non-Repudiation | E7: TRUE | F7: DigiCert | G7: USD | H7: 012dp000005zfL7AAI | J7: 01t0z000007f410AAA | K7: 01t0z000007f410AAA | L7: 01t0z000007f410AAA | S7: 11BWC000002WLhp2AG | V7: TRUE | W7: Allowed | X7: TRUE | Y7: Commercial | Z7: FALSE | BG7: FALSE | CD7: FALSE | CG7: FALSE | CL7: FALSE | CM7: FALSE | CN7: FALSE | CP7: 01tWC00000AYBY3YAP | CR7: FALSE | CV7: FALSE | CX7: FALSE | CY7: FALSE | DA7: FALSE | DB7: FALSE | DI7: FALSE | DN7: Authentication Only - Non-Repudiation | DQ7: FALSE | DS7: FALSE | DU7: Authentication Only - Non-Repudiation | DZ7: Active
A8: [Product2] | B8: Authentication Plus | C8: Authentication Plus | E8: TRUE | F8: DigiCert | G8: USD | H8: 012dp000005zfL7AAI | J8: 01t0z000007f411AAA | K8: 01t0z000007f411AAA | L8: 01t0z000007f411AAA | S8: 11BWC000002WLhl2AG | V8: TRUE | W8: Allowed | X8: TRUE | Y8: Commercial | Z8: FALSE | BG8: FALSE | CD8: FALSE | CG8: FALSE | CL8: FALSE | CM8: FALSE | CN8: FALSE | CP8: 01tWC00000AYBY4YAP | CR8: FALSE | CV8: FALSE | CX8: FALSE | CY8: FALSE | DA8: FALSE | DB8: FALSE | DI8: FALSE | DN8: Authentication Plus | DQ8: FALSE | DS8: FALSE | DU8: Authentication Plus | DZ8: Active
A9: [Product2] | B9: Authentication Plus (AD Integration) | C9: Authentication Plus (AD Integration) | E9: TRUE | F9: DigiCert | G9: USD | H9: 012dp000005zfL7AAI | J9: 01t0z000007f412AAA | K9: 01t0z000007f412AAA | L9: 01t0z000007f412AAA | S9: 11BWC000002WLYo2AO | V9: TRUE | W9: Allowed | X9: TRUE | Y9: Commercial | Z9: FALSE | BG9: FALSE | CD9: FALSE | CG9: FALSE | CL9: FALSE | CM9: FALSE | CN9: FALSE | CP9: 01tWC00000AYBY5YAP | CR9: FALSE | CV9: FALSE | CX9: FALSE | CY9: FALSE | DA9: FALSE | DB9: FALSE | DI9: FALSE | DN9: Authentication Plus (AD Integration) | DQ9: FALSE | DS9: FALSE | DU9: Authentication Plus (AD Integration) | DZ9: Active
A10: [Product2] | B10: Basic EV | C10: Basic EV | E10: TRUE | F10: DigiCert | G10: USD | H10: 012dp000005zfL7AAI | J10: 01t0z000007f413AAA | K10: 01t0z000007f413AAA | L10: 01t0z000007f413AAA | V10: TRUE | W10: Allowed | X10: TRUE | Y10: Commercial | Z10: FALSE | BG10: FALSE | CD10: FALSE | CG10: FALSE | CL10: FALSE | CM10: FALSE | CN10: FALSE | CP10: 01tWC00000AYBY6YAP | CR10: FALSE | CV10: FALSE | CX10: FALSE | CY10: FALSE | DA10: FALSE | DB10: FALSE | DI10: FALSE | DN10: Basic EV | DQ10: FALSE | DS10: FALSE | DU10: Basic EV | DY10: All SSL Product Grp | DZ10: Active
A11: [Product2] | B11: Basic EV FQDN SAN | C11: Basic EV FQDN SAN | E11: TRUE | F11: DigiCert | G11: USD | H11: 012dp000005zfL7AAI | J11: 01t0z000007f414AAA | K11: 01t0z000007f414AAA | L11: 01t0z000007f414AAA | S11: 11BWC000002cka92AA | V11: TRUE | X11: TRUE | Y11: Commercial | Z11: FALSE | BG11: FALSE | CD11: FALSE | CG11: FALSE | CL11: FALSE | CM11: FALSE | CN11: FALSE | CP11: 01tWC00000AYBY7YAP | CR11: FALSE | CV11: FALSE | CX11: FALSE | CY11: FALSE | DA11: FALSE | DB11: FALSE | DI11: FALSE | DN11: Basic EV FQDN SAN | DQ11: FALSE | DS11: FALSE | DU11: Basic EV FQDN SAN | DY11: All SSL Product Grp | DZ11: Active
A12: [Product2] | B12: Basic OV | C12: Basic OV | E12: TRUE | F12: DigiCert | G12: USD | H12: 012dp000005zfL7AAI | J12: 01t0z000007f415AAA | K12: 01t0z000007f415AAA | L12: 01t0z000007f415AAA | V12: TRUE | W12: Allowed | X12: TRUE | Y12: Commercial | Z12: FALSE | BG12: FALSE | CD12: FALSE | CG12: FALSE | CL12: FALSE | CM12: FALSE | CN12: FALSE | CP12: 01tWC00000AYBY8YAP | CR12: FALSE | CV12: FALSE | CX12: FALSE | CY12: FALSE | DA12: FALSE | DB12: FALSE | DI12: FALSE | DN12: Basic OV | DQ12: FALSE | DS12: FALSE | DU12: Basic OV | DY12: All SSL Product Grp | DZ12: Active
A13: [Product2] | B13: Basic OV FQDN SAN | C13: Basic OV FQDN SAN | E13: TRUE | F13: DigiCert | G13: USD | H13: 012dp000005zfL7AAI | J13: 01t0z000007f416AAA | K13: 01t0z000007f416AAA | L13: 01t0z000007f416AAA | S13: 11BWC000002cka92AA | V13: TRUE | X13: TRUE | Y13: Commercial | Z13: FALSE | BG13: FALSE | CD13: FALSE | CG13: FALSE | CL13: FALSE | CM13: FALSE | CN13: FALSE | CP13: 01tWC00000AYBY9YAP | CR13: FALSE | CV13: FALSE | CX13: FALSE | CY13: FALSE | DA13: FALSE | DB13: FALSE | DI13: FALSE | DN13: Basic OV FQDN SAN | DQ13: FALSE | DS13: FALSE | DU13: Basic OV FQDN SAN | DY13: All SSL Product Grp | DZ13: Active
A14: [Product2] | B14: Basic OV Wildcard SAN | C14: Basic OV Wildcard SAN | E14: TRUE | F14: DigiCert | G14: USD | H14: 012dp000005zfL7AAI | J14: 01t0z000007f417AAA | K14: 01t0z000007f417AAA | L14: 01t0z000007f417AAA | S14: 11BWC000002cka92AA | V14: TRUE | X14: TRUE | Y14: Commercial | Z14: FALSE | BG14: FALSE | CD14: FALSE | CG14: FALSE | CL14: FALSE | CM14: FALSE | CN14: FALSE | CP14: 01tWC00000AYBYAYA5 | CR14: FALSE | CV14: FALSE | CX14: FALSE | CY14: FALSE | DA14: FALSE | DB14: FALSE | DI14: FALSE | DN14: Basic OV Wildcard SAN | DQ14: FALSE | DS14: FALSE | DU14: Basic OV Wildcard SAN | DY14: All SSL Product Grp | DZ14: Active
A15: [Product2] | B15: Class 1 S/MIME | C15: Class 1 S/MIME | E15: TRUE | F15: DigiCert | G15: USD | H15: 012dp000005zfL7AAI | J15: 01t0z000007f418AAA | K15: 01t0z000007f418AAA | L15: 01t0z000007f418AAA | S15: 11BWC000002WLhq2AG | V15: TRUE | W15: Allowed | X15: TRUE | Y15: Commercial | Z15: FALSE | BG15: FALSE | CD15: FALSE | CG15: FALSE | CL15: FALSE | CM15: FALSE | CN15: FALSE | CP15: 01tWC00000AYBYBYA5 | CR15: FALSE | CV15: FALSE | CX15: FALSE | CY15: FALSE | DA15: FALSE | DB15: FALSE | DI15: FALSE | DN15: Class 1 S/MIME | DQ15: FALSE | DS15: FALSE | DU15: Class 1 S/MIME | DZ15: Active
A16: [Product2] | B16: Code Signing | C16: Code Signing | E16: TRUE | F16: DigiCert | G16: USD | H16: 012dp000005zfL7AAI | J16: 01t0z000007f419AAA | K16: 01t0z000007f419AAA | L16: 01t0z000007f419AAA | S16: 11BWC000002WLhh2AG | V16: TRUE | W16: Allowed | X16: TRUE | Y16: Commercial | Z16: FALSE | BG16: FALSE | CD16: FALSE | CG16: FALSE | CL16: FALSE | CM16: FALSE | CN16: FALSE | CP16: 01tWC00000AYBYCYA5 | CR16: FALSE | CV16: FALSE | CX16: FALSE | CY16: FALSE | DA16: FALSE | DB16: FALSE | DI16: FALSE | DN16: Code Signing | DQ16: FALSE | DS16: FALSE | DU16: Code Signing | DZ16: Active
A17: [Product2] | B17: Digital Signature Plus | C17: Digital Signature Plus | E17: TRUE | F17: DigiCert | G17: USD | H17: 012dp000005zfL7AAI | J17: 01t0z000007f41AAAQ | K17: 01t0z000007f41AAAQ | L17: 01t0z000007f41AAAQ | S17: 11BWC000002WLhj2AG | V17: TRUE | W17: Allowed | X17: TRUE | Y17: Commercial | Z17: FALSE | BG17: FALSE | CD17: FALSE | CG17: FALSE | CL17: FALSE | CM17: FALSE | CN17: FALSE | CP17: 01tWC00000AYBYDYA5 | CR17: FALSE | CV17: FALSE | CX17: FALSE | CY17: FALSE | DA17: FALSE | DB17: FALSE | DI17: FALSE | DN17: Digital Signature Plus | DQ17: FALSE | DS17: FALSE | DU17: Digital Signature Plus | DZ17: Active
A18: [Product2] | B18: Email Security Plus | C18: Email Security Plus | E18: TRUE | F18: DigiCert | G18: USD | H18: 012dp000005zfL7AAI | J18: 01t0z000007f41DAAQ | K18: 01t0z000007f41DAAQ | L18: 01t0z000007f41DAAQ | S18: 11BWC000002WLhk2AG | V18: TRUE | W18: Allowed | X18: TRUE | Y18: Commercial | Z18: FALSE | BG18: FALSE | CD18: FALSE | CG18: FALSE | CL18: FALSE | CM18: FALSE | CN18: FALSE | CP18: 01tWC00000AYBYEYA5 | CR18: FALSE | CV18: FALSE | CX18: FALSE | CY18: FALSE | DA18: FALSE | DB18: FALSE | DI18: FALSE | DN18: Email Security Plus | DQ18: FALSE | DS18: FALSE | DU18: Email Security Plus | DZ18: Active
A19: [Product2] | B19: Email Security Plus (AD Integration) | C19: Email Security Plus (AD Integration) | E19: TRUE | F19: DigiCert | G19: USD | H19: 012dp000005zfL7AAI | J19: 01t0z000007f41EAAQ | K19: 01t0z000007f41EAAQ | L19: 01t0z000007f41EAAQ | S19: 11BWC000002WLYm2AO | V19: TRUE | W19: Allowed | X19: TRUE | Y19: Commercial | Z19: FALSE | BG19: FALSE | CD19: FALSE | CG19: FALSE | CL19: FALSE | CM19: FALSE | CN19: FALSE | CP19: 01tWC00000AYBYFYA5 | CR19: FALSE | CV19: FALSE | CX19: FALSE | CY19: FALSE | DA19: FALSE | DB19: FALSE | DI19: FALSE | DN19: Email Security Plus (AD Integration) | DQ19: FALSE | DS19: FALSE | DU19: Email Security Plus (AD Integration) | DZ19: Active
A20: [Product2] | B20: Email Security Plus [SHA-2 Only] | C20: Email Security Plus [SHA-2 Only] | E20: TRUE | F20: DigiCert | G20: USD | H20: 012dp000005zfL7AAI | J20: 01t0z000007f41FAAQ | K20: 01t0z000007f41FAAQ | L20: 01t0z000007f41FAAQ | S20: 11BWC000002WLYn2AO | V20: TRUE | W20: Allowed | X20: TRUE | Y20: Commercial | Z20: FALSE | BG20: FALSE | CD20: FALSE | CG20: FALSE | CL20: FALSE | CM20: FALSE | CN20: FALSE | CP20: 01tWC00000AYBYGYA5 | CR20: FALSE | CV20: FALSE | CX20: FALSE | CY20: FALSE | DA20: FALSE | DB20: FALSE | DI20: FALSE | DN20: Email Security Plus [SHA-2 Only] | DQ20: FALSE | DS20: FALSE | DU20: Email Security Plus [SHA-2 Only] | DY20: All SSL Product Grp | DZ20: Active
A21: [Product2] | B21: EV Code Signing | C21: EV Code Signing | E21: TRUE | F21: DigiCert | G21: USD | H21: 012dp000005zfL7AAI | J21: 01t0z000007f41GAAQ | K21: 01t0z000007f41GAAQ | L21: 01t0z000007f41GAAQ | S21: 11BWC000002WLhi2AG | V21: TRUE | W21: Allowed | X21: TRUE | Y21: Commercial | Z21: FALSE | BG21: FALSE | CD21: FALSE | CG21: FALSE | CL21: FALSE | CM21: FALSE | CN21: FALSE | CP21: 01tWC00000AYBYHYA5 | CR21: FALSE | CV21: FALSE | CX21: FALSE | CY21: FALSE | DA21: FALSE | DB21: FALSE | DI21: FALSE | DN21: EV Code Signing | DQ21: FALSE | DS21: FALSE | DU21: EV Code Signing | DZ21: Active
A22: [Product2] | B22: GeoTrust Flex DV | C22: GeoTrust Flex DV | E22: TRUE | F22: Geotrust | G22: USD | H22: 012dp000005zfL7AAI | J22: 01t0z000007f41HAAQ | K22: 01t0z000007f41HAAQ | L22: 01t0z000007f41HAAQ | V22: TRUE | W22: Allowed | X22: TRUE | Y22: Commercial | Z22: FALSE | BG22: FALSE | CD22: FALSE | CG22: FALSE | CL22: FALSE | CM22: FALSE | CN22: FALSE | CP22: 01tWC00000AYBYIYA5 | CR22: FALSE | CV22: FALSE | CX22: FALSE | CY22: FALSE | DA22: FALSE | DB22: FALSE | DI22: FALSE | DN22: GeoTrust Flex DV | DQ22: FALSE | DS22: FALSE | DU22: GeoTrust Flex DV | DY22: All SSL Product Grp | DZ22: Active
A23: [Product2] | B23: GeoTrust Flex DV FQDN SAN | C23: GeoTrust Flex DV FQDN SAN | E23: TRUE | F23: Geotrust | G23: USD | H23: 012dp000005zfL7AAI | J23: 01t0z000007f41IAAQ | K23: 01t0z000007f41IAAQ | L23: 01t0z000007f41IAAQ | S23: 11BWC000002cka92AA | V23: TRUE | X23: TRUE | Y23: Commercial | Z23: FALSE | BG23: FALSE | CD23: FALSE | CG23: FALSE | CL23: FALSE | CM23: FALSE | CN23: FALSE | CP23: 01tWC00000AYBYJYA5 | CR23: FALSE | CV23: FALSE | CX23: FALSE | CY23: FALSE | DA23: FALSE | DB23: FALSE | DI23: FALSE | DN23: GeoTrust Flex DV FQDN SAN | DQ23: FALSE | DS23: FALSE | DU23: GeoTrust Flex DV FQDN SAN | DY23: All SSL Product Grp | DZ23: Active
A24: [Product2] | B24: GeoTrust Flex DV Wildcard SAN | C24: GeoTrust Flex DV Wildcard SAN | E24: TRUE | F24: Geotrust | G24: USD | H24: 012dp000005zfL7AAI | J24: 01t0z000007f41JAAQ | K24: 01t0z000007f41JAAQ | L24: 01t0z000007f41JAAQ | S24: 11BWC000002cka92AA | V24: TRUE | X24: TRUE | Y24: Commercial | Z24: FALSE | BG24: FALSE | CD24: FALSE | CG24: FALSE | CL24: FALSE | CM24: FALSE | CN24: FALSE | CP24: 01tWC00000AYBYKYA5 | CR24: FALSE | CV24: FALSE | CX24: FALSE | CY24: FALSE | DA24: FALSE | DB24: FALSE | DI24: FALSE | DN24: GeoTrust Flex DV Wildcard SAN | DQ24: FALSE | DS24: FALSE | DU24: GeoTrust Flex DV Wildcard SAN | DY24: All SSL Product Grp | DZ24: Active
A25: [Product2] | B25: GeoTrust TrueBusiness ID EV | C25: GeoTrust TrueBusiness ID EV | E25: TRUE | F25: Geotrust | G25: USD | H25: 012dp000005zfL7AAI | J25: 01t0z000007f41KAAQ | K25: 01t0z000007f41KAAQ | L25: 01t0z000007f41KAAQ | V25: TRUE | W25: Allowed | X25: TRUE | Y25: Commercial | Z25: FALSE | BG25: FALSE | CD25: FALSE | CG25: FALSE | CL25: FALSE | CM25: FALSE | CN25: FALSE | CP25: 01tWC00000AYBYLYA5 | CR25: FALSE | CV25: FALSE | CX25: FALSE | CY25: FALSE | DA25: FALSE | DB25: FALSE | DI25: FALSE | DN25: GeoTrust TrueBusiness ID EV | DQ25: FALSE | DS25: FALSE | DU25: GeoTrust TrueBusiness ID EV | DZ25: Active
A26: [Product2] | B26: GeoTrust TrueBusiness ID EV FQDN SAN | C26: GeoTrust TrueBusiness ID EV FQDN SAN | E26: TRUE | F26: Geotrust | G26: USD | H26: 012dp000005zfL7AAI | J26: 01t0z000007f41LAAQ | K26: 01t0z000007f41LAAQ | L26: 01t0z000007f41LAAQ | S26: 11BWC000002cka92AA | V26: TRUE | X26: TRUE | Y26: Commercial | Z26: FALSE | BG26: FALSE | CD26: FALSE | CG26: FALSE | CL26: FALSE | CM26: FALSE | CN26: FALSE | CP26: 01tWC00000AYBYMYA5 | CR26: FALSE | CV26: FALSE | CX26: FALSE | CY26: FALSE | DA26: FALSE | DB26: FALSE | DI26: FALSE | DN26: GeoTrust TrueBusiness ID EV FQDN SAN | DQ26: FALSE | DS26: FALSE | DU26: GeoTrust TrueBusiness ID EV FQDN SAN | DY26: All SSL Product Grp | DZ26: Active
A27: [Product2] | B27: GeoTrust TrueBusiness ID OV | C27: GeoTrust TrueBusiness ID OV | E27: TRUE | F27: Geotrust | G27: USD | H27: 012dp000005zfL7AAI | J27: 01t0z000007f41MAAQ | K27: 01t0z000007f41MAAQ | L27: 01t0z000007f41MAAQ | V27: TRUE | W27: Allowed | X27: TRUE | Y27: Commercial | Z27: FALSE | BG27: FALSE | CD27: FALSE | CG27: FALSE | CL27: FALSE | CM27: FALSE | CN27: FALSE | CP27: 01tWC00000AYBYNYA5 | CR27: FALSE | CV27: FALSE | CX27: FALSE | CY27: FALSE | DA27: FALSE | DB27: FALSE | DI27: FALSE | DN27: GeoTrust TrueBusiness ID OV | DQ27: FALSE | DS27: FALSE | DU27: GeoTrust TrueBusiness ID OV | DZ27: Active
A28: [Product2] | B28: GeoTrust TrueBusiness ID OV FQDN SAN | C28: GeoTrust TrueBusiness ID OV FQDN SAN | E28: TRUE | F28: Geotrust | G28: USD | H28: 012dp000005zfL7AAI | J28: 01t0z000007f41NAAQ | K28: 01t0z000007f41NAAQ | L28: 01t0z000007f41NAAQ | S28: 11BWC000002cka92AA | V28: TRUE | X28: TRUE | Y28: Commercial | Z28: FALSE | BG28: FALSE | CD28: FALSE | CG28: FALSE | CL28: FALSE | CM28: FALSE | CN28: FALSE | CP28: 01tWC00000AYBYOYA5 | CR28: FALSE | CV28: FALSE | CX28: FALSE | CY28: FALSE | DA28: FALSE | DB28: FALSE | DI28: FALSE | DN28: GeoTrust TrueBusiness ID OV FQDN SAN | DQ28: FALSE | DS28: FALSE | DU28: GeoTrust TrueBusiness ID OV FQDN SAN | DY28: All SSL Product Grp | DZ28: Active
A29: [Product2] | B29: GeoTrust TrueBusiness ID OV Wildcard SAN | C29: GeoTrust TrueBusiness ID OV Wildcard SAN | E29: TRUE | F29: Geotrust | G29: USD | H29: 012dp000005zfL7AAI | J29: 01t0z000007f41OAAQ | K29: 01t0z000007f41OAAQ | L29: 01t0z000007f41OAAQ | S29: 11BWC000002cka92AA | V29: TRUE | X29: TRUE | Y29: Commercial | Z29: FALSE | BG29: FALSE | CD29: FALSE | CG29: FALSE | CL29: FALSE | CM29: FALSE | CN29: FALSE | CP29: 01tWC00000AYBYPYA5 | CR29: FALSE | CV29: FALSE | CX29: FALSE | CY29: FALSE | DA29: FALSE | DB29: FALSE | DI29: FALSE | DN29: GeoTrust TrueBusiness ID OV Wildcard SAN | DQ29: FALSE | DS29: FALSE | DU29: GeoTrust TrueBusiness ID OV Wildcard SAN | DY29: All SSL Product Grp | DZ29: Active
A30: [Product2] | B30: LTANS Adobe Signing | C30: LTANS Adobe Signing | E30: TRUE | F30: DigiCert | G30: USD | H30: 012dp000005zfL7AAI | J30: 01t0z000007f41PAAQ | K30: 01t0z000007f41PAAQ | L30: 01t0z000007f41PAAQ | S30: 11BWC000002WLYs2AO | V30: TRUE | W30: Allowed | X30: TRUE | Y30: Commercial | Z30: FALSE | BG30: FALSE | CD30: FALSE | CG30: FALSE | CL30: FALSE | CM30: FALSE | CN30: FALSE | CP30: 01tWC00000AYBYQYA5 | CR30: FALSE | CV30: FALSE | CX30: FALSE | CY30: FALSE | DA30: FALSE | DB30: FALSE | DI30: FALSE | DN30: LTANS Adobe Signing | DQ30: FALSE | DS30: FALSE | DU30: LTANS Adobe Signing | DZ30: Active
A31: [Product2] | B31: Multi-Name Client Auth | C31: Multi-Name Client Auth | E31: TRUE | F31: DigiCert | G31: USD | H31: 012dp000005zfL7AAI | J31: 01t0z000007f41QAAQ | K31: 01t0z000007f41QAAQ | L31: 01t0z000007f41QAAQ | S31: 11BWC000002WLho2AG | V31: TRUE | W31: Allowed | X31: TRUE | Y31: Commercial | Z31: FALSE | BG31: FALSE | CD31: FALSE | CG31: FALSE | CL31: FALSE | CM31: FALSE | CN31: FALSE | CP31: 01tWC00000AYBYRYA5 | CR31: FALSE | CV31: FALSE | CX31: FALSE | CY31: FALSE | DA31: FALSE | DB31: FALSE | DI31: FALSE | DN31: Multi-Name Client Auth | DQ31: FALSE | DS31: FALSE | DU31: Multi-Name Client Auth | DZ31: Active
A32: [Product2] | B32: Premium (Class 2 S/MIME) | C32: Premium (Class 2 S/MIME) | E32: TRUE | F32: DigiCert | G32: USD | H32: 012dp000005zfL7AAI | J32: 01t0z000007f41SAAQ | K32: 01t0z000007f41SAAQ | L32: 01t0z000007f41SAAQ | S32: 11BWC000002WLhm2AG | V32: TRUE | W32: Allowed | X32: TRUE | Y32: Commercial | Z32: FALSE | BG32: FALSE | CD32: FALSE | CG32: FALSE | CL32: FALSE | CM32: FALSE | CN32: FALSE | CP32: 01tWC00000AYBYTYA5 | CR32: FALSE | CV32: FALSE | CX32: FALSE | CY32: FALSE | DA32: FALSE | DB32: FALSE | DI32: FALSE | DN32: Premium (Class 2 S/MIME) | DQ32: FALSE | DS32: FALSE | DU32: Premium (Class 2 S/MIME) | DZ32: Active
A33: [Product2] | B33: Premium - Data Encipherment | C33: Premium - Data Encipherment | E33: TRUE | F33: DigiCert | G33: USD | H33: 012dp000005zfL7AAI | J33: 01t0z000007f41TAAQ | K33: 01t0z000007f41TAAQ | L33: 01t0z000007f41TAAQ | S33: 11BWC000002WLYx2AO | V33: TRUE | W33: Allowed | X33: TRUE | Y33: Commercial | Z33: FALSE | BG33: FALSE | CD33: FALSE | CG33: FALSE | CL33: FALSE | CM33: FALSE | CN33: FALSE | CP33: 01tWC00000AYBYUYA5 | CR33: FALSE | CV33: FALSE | CX33: FALSE | CY33: FALSE | DA33: FALSE | DB33: FALSE | DI33: FALSE | DN33: Premium - Data Encipherment | DQ33: FALSE | DS33: FALSE | DU33: Premium - Data Encipherment | DZ33: Active
A34: [Product2] | B34: Premium - Non-Repudiation | C34: Premium - Non-Repudiation | E34: TRUE | F34: DigiCert | G34: USD | H34: 012dp000005zfL7AAI | J34: 01t0z000007f41UAAQ | K34: 01t0z000007f41UAAQ | L34: 01t0z000007f41UAAQ | S34: 11BWC000002WLYw2AO | V34: TRUE | W34: Allowed | X34: TRUE | Y34: Commercial | Z34: FALSE | BG34: FALSE | CD34: FALSE | CG34: FALSE | CL34: FALSE | CM34: FALSE | CN34: FALSE | CP34: 01tWC00000AYBYVYA5 | CR34: FALSE | CV34: FALSE | CX34: FALSE | CY34: FALSE | DA34: FALSE | DB34: FALSE | DI34: FALSE | DN34: Premium - Non-Repudiation | DQ34: FALSE | DS34: FALSE | DU34: Premium - Non-Repudiation | DZ34: Active
A35: [Product2] | B35: Premium (AD Integration) | C35: Premium (AD Integration) | E35: TRUE | F35: DigiCert | G35: USD | H35: 012dp000005zfL7AAI | J35: 01t0z000007f41VAAQ | K35: 01t0z000007f41VAAQ | L35: 01t0z000007f41VAAQ | S35: 11BWC000002WLYq2AO | V35: TRUE | W35: Allowed | X35: TRUE | Y35: Commercial | Z35: FALSE | BG35: FALSE | CD35: FALSE | CG35: FALSE | CL35: FALSE | CM35: FALSE | CN35: FALSE | CP35: 01tWC00000AYBYWYA5 | CR35: FALSE | CV35: FALSE | CX35: FALSE | CY35: FALSE | DA35: FALSE | DB35: FALSE | DI35: FALSE | DN35: Premium (AD Integration) | DQ35: FALSE | DS35: FALSE | DU35: Premium (AD Integration) | DZ35: Active
A36: [Product2] | B36: Premium [SHA-2 Only] | C36: Premium [SHA-2 Only] | E36: TRUE | F36: DigiCert | G36: USD | H36: 012dp000005zfL7AAI | J36: 01t0z000007f41WAAQ | K36: 01t0z000007f41WAAQ | L36: 01t0z000007f41WAAQ | S36: 11BWC000002WLYr2AO | V36: TRUE | W36: Allowed | X36: TRUE | Y36: Commercial | Z36: FALSE | BG36: FALSE | CD36: FALSE | CG36: FALSE | CL36: FALSE | CM36: FALSE | CN36: FALSE | CP36: 01tWC00000AYBYXYA5 | CR36: FALSE | CV36: FALSE | CX36: FALSE | CY36: FALSE | DA36: FALSE | DB36: FALSE | DI36: FALSE | DN36: Premium [SHA-2 Only] | DQ36: FALSE | DS36: FALSE | DU36: Premium [SHA-2 Only] | DY36: All SSL Product Grp | DZ36: Active
A37: [Product2] | B37: Private Premium | C37: 1022 | E37: TRUE | F37: DigiCert | G37: USD | H37: 012dp000005zfL7AAI | J37: 01t0z000007f41XAAQ | K37: 01t0z000007f41XAAQ | L37: 01t0z000007f41XAAQ | S37: 11BWC000002WLYu2AO | V37: TRUE | W37: Allowed | X37: TRUE | Y37: Commercial | Z37: FALSE | BG37: FALSE | CD37: FALSE | CG37: FALSE | CL37: FALSE | CM37: FALSE | CN37: FALSE | CP37: 01tWC00000AYBYYYA5 | CR37: FALSE | CV37: FALSE | CX37: FALSE | CY37: FALSE | DA37: FALSE | DB37: FALSE | DI37: FALSE | DN37: 1022 | DQ37: FALSE | DS37: FALSE | DU37: Private Premium | DZ37: Active
A38: [Product2] | B38: Private SSL Base | C38: Private SSL Base | E38: TRUE | F38: DigiCert | G38: USD | H38: 012dp000005zfL7AAI | J38: 01t0z000007f41YAAQ | K38: 01t0z000007f41YAAQ | L38: 01t0z000007f41YAAQ | S38: 11BWC000002WLYl2AO | V38: TRUE | W38: Allowed | X38: TRUE | Y38: Commercial | Z38: FALSE | BG38: FALSE | CD38: FALSE | CG38: FALSE | CL38: FALSE | CM38: FALSE | CN38: FALSE | CP38: 01tWC00000AYBYZYA5 | CR38: FALSE | CV38: FALSE | CX38: FALSE | CY38: FALSE | DA38: FALSE | DB38: FALSE | DI38: FALSE | DN38: Private SSL Base | DQ38: FALSE | DS38: FALSE | DU38: Private SSL Base | DY38: All SSL Product Grp | DZ38: Active
A39: [Product2] | B39: Private SSL FQDN SAN | C39: Private SSL FQDN SAN | E39: TRUE | F39: DigiCert | G39: USD | H39: 012dp000005zfL7AAI | J39: 01t0z000007f41ZAAQ | K39: 01t0z000007f41ZAAQ | L39: 01t0z000007f41ZAAQ | S39: 11BWC000002WLhs2AG | V39: TRUE | W39: Allowed | X39: TRUE | Y39: Commercial | Z39: FALSE | BG39: FALSE | CD39: FALSE | CG39: FALSE | CL39: FALSE | CM39: FALSE | CN39: FALSE | CP39: 01tWC00000AYBYaYAP | CR39: FALSE | CV39: FALSE | CX39: FALSE | CY39: FALSE | DA39: FALSE | DB39: FALSE | DI39: FALSE | DN39: Private SSL FQDN SAN | DQ39: FALSE | DS39: FALSE | DU39: Private SSL FQDN SAN | DY39: All SSL Product Grp | DZ39: Active
A40: [Product2] | B40: Private SSL Wildcard SAN | C40: Private SSL Wildcard SAN | E40: TRUE | F40: DigiCert | G40: USD | H40: 012dp000005zfL7AAI | J40: 01t0z000007f41aAAA | K40: 01t0z000007f41aAAA | L40: 01t0z000007f41aAAA | S40: 11BWC000002WLhr2AG | V40: TRUE | W40: Allowed | X40: TRUE | Y40: Commercial | Z40: FALSE | BG40: FALSE | CD40: FALSE | CG40: FALSE | CL40: FALSE | CM40: FALSE | CN40: FALSE | CP40: 01tWC00000AYBYbYAP | CR40: FALSE | CV40: FALSE | CX40: FALSE | CY40: FALSE | DA40: FALSE | DB40: FALSE | DI40: FALSE | DN40: Private SSL Wildcard SAN | DQ40: FALSE | DS40: FALSE | DU40: Private SSL Wildcard SAN | DY40: All SSL Product Grp | DZ40: Active
...

Sheet Sheet3
A1: _ | B1: Name | C1: ProductCode | D1: Description | E1: IsActive | F1: Family | G1: CurrencyIsoCode | H1: RecordTypeId | I1: ExternalDataSourceId | J1: Id | K1: RCA_ExternalId__c | L1: ExternalId | M1: DisplayUrl | N1: QuantityUnitOfMeasure | O1: StockKeepingUnit | P1: AvailabilityDate | Q1: DiscontinuedDate | R1: BasedOn:ProductClassification:RCA_ExternalId__c | S1: EndOfLifeDate | T1: HelpText | U1: IsAssetizable | V1: ConfigureDuringSale | W1: IsSoldOnlyWithOtherProds | X1: _SpecificationType | Y1: _CanRamp | Z1: UsageModelType | AA1: Product_Type__c | AB1: GLOBAL_SPECIALIZATION__c | AC1: Internal_Peak__c | AD1: Oracle_Product_Code__c | AE1: Part_Number__c | AF1: Product_Category__c | AG1: Product_Family_Description__c | AH1: Product_Information__c | AI1: Product_Subcategory__c | AJ1: Quotable_Flag__c | AK1: SYMC_CreatedByID__c | AL1: SYMC_LastModifiedByID__c | AM1: Apttus_Config2__BundleInvoiceLevel__c | AN1: Zproduct_Id__c | AO1: Offering_Type__c | AP1: Admin_Area_ID__c | AQ1: Apttus_Config2__RenewalLeadTime__c | AR1: Category_L__c | AS1: Cost__c | AT1: FA_product_line__c | AU1: Genkaritsu__c | AV1: Hanbai_Keitai__c | AW1: Num_Hanbai__c | AX1: Product_Bunrui__c | AY1: Public_Private__c | AZ1: US_Report_Category__c | BA1: activedate_from__c | BB1: activedate_to__c | BC1: category_M__c | BD1: category_s__c | BE1: defered_term__c | BF1: delete_flags__c | BG1: ebs_account__c | BH1: ebs_business_unit__c | BI1: ebs_business_unit_description__c | BJ1: ebs_customer_order_enabled_flag__c | BK1: ebs_customer_order_flag__c | BL1: ebs_description__c | BM1: ebs_enabled_flag__c | BN1: ebs_invoice_enabled_flag__c | BO1: ebs_invoiceable_item_flag__c | BP1: ebs_item_id__c | BQ1: ebs_item_num__c | BR1: ebs_item_type__c | BS1: ebs_language__c | BT1: ebs_language_description__c | BU1: ebs_master_description__c | BV1: ebs_organization_id__c | BW1: ebs_product_line__c | BX1: ebs_product_line_description__c | BY1: ebs_product_name__c | BZ1: ebs_tax_code__c | CA1: ebs_unit_of_issue__c | CB1: kame_product_id__c | CC1: product_flag__c | CD1: revenue_type_id__c | CE1: servicelist__c | CF1: APTS_Apttus_Product__c | CG1: APTS_Cert_Category__c | CH1: APTS_Console__c | CI1: APTS_Contract_Consumption_Method__c | CJ1: APTS_Ext_ID__c | CK1: APTS_Is_Amendable__c | CL1: APTS_Is_Renewable__c | CM1: APTS_New_CPQ_CertCentral__c | CN1: APTS_Order__c | CO1: _APTS_Product_Id_18__c | CP1: APTS_Product_Line__c | CQ1: APTS_Requires_CPF_Doc__c | CR1: APTS_Target_Channel__c | CS1: Type_QV__c | CT1: APTS_Config_Schema__c | CU1: APTS_Exclude_from_Ramping_Validation__c | CV1: ebs_invoicing_rule_id__c | CW1: APTS_Exclude_From_Channel_Discounts__c | CX1: APTS_True_Up_Product__c | CY1: APTS_Japanese_Product_Name__c | CZ1: Non_Recurring_Checkbox__c | DA1: Non_Future_Contracted__c | DB1: cc_product_api_id__c | DC1: APTS_Product_Category__c | DD1: APTS_Product_Line_L2__c | DE1: APTS_Product_Organisation_L1__c | DF1: APTS_Product_category_L3__c | DG1: APTS_Attributes_To_Consider_SKU__c | DH1: APTS_Do_not_consider_for_SKU_Code__c | DI1: APTS_no_of_attributes_SKU__c | DJ1: _APTS_Level1_Abbrv__c | DK1: _APTS_Level_2_Abbrv__c | DL1: _APTS_Level_3_Abbrv__c | DM1: _APTS_Product_Code_with_SKU__c | DN1: _APTS_SKU_Code__c | DO1: Product_Category_SFDC__c | DP1: APTS_Is_MSP_Quotable__c | DQ1: Charge_Type__c | DR1: Is_Manual__c | DS1: Overage_Rate__c | DT1: _Product_Alias__c | DU1: Product_Group__c | DV1: Unit__c | DW1: Charge_Model__c | DX1: ProductGroup__c | DY1: RCA_Lifecycle_Status__c | DZ1: __Status | EA1: __Id | EB1: __Action | EC1: __Errors
A2: [Product2] | B2: Grid Robot Name | C2: Grid Robot Name | E2: TRUE | F2: DigiCert | G2: USD | H2: 012dp000005zfL7AAI | J2: 01t4z000008h0NLAAY | K2: 01t4z000008h0NLAAY | L2: 01t4z000008h0NLAAY | R2: 11BWC000002WLZ42AO | U2: TRUE | W2: TRUE | X2: Commercial | Y2: FALSE | BF2: FALSE | CC2: FALSE | CF2: FALSE | CK2: FALSE | CL2: FALSE | CM2: FALSE | CO2: 01tWC00000AYBXxYAP | CQ2: FALSE | CU2: FALSE | CW2: FALSE | CX2: FALSE | CZ2: FALSE | DA2: FALSE | DH2: FALSE | DM2: Grid Robot Name | DP2: FALSE | DR2: FALSE | DT2: Grid Robot Name | DX2: All SSL Product Grp | DY2: Active | DZ2: Failed | EA2: 01t4z000008h0NLAAY | EC2: INVALID_FIELD_FOR_INSERT_UPDATE: Unable to create/update fields: APTS_Product_Id_18__c, Type. Please check the security settings of this field and verify that it is read/write for your profile or permission set. [APTS_Product_Id_18__c, Type]
A3: [Product2] | B3: Verified Mark Certificate FQDN Price | C3: 99 | E3: TRUE | F3: DigiCert | G3: USD | H3: 012dp000005zfL7AAI | J3: 01t4z000008iBW3AAM | K3: 01t4z000008iBW3AAM | L3: 01t4z000008iBW3AAM | R3: 11BWC000002cka92AA | U3: TRUE | W3: TRUE | X3: Commercial | Y3: FALSE | BF3: FALSE | CC3: FALSE | CF3: FALSE | CK3: FALSE | CL3: FALSE | CM3: FALSE | CO3: 01tWC00000AYBXyYAP | CQ3: FALSE | CU3: FALSE | CW3: FALSE | CX3: FALSE | CZ3: FALSE | DA3: FALSE | DH3: FALSE | DM3: 99 | DP3: FALSE | DR3: FALSE | DT3: Verified Mark Certificate FQDN Price | DX3: All SSL Product Grp | DY3: Active | DZ3: Failed | EA3: 01t4z000008iBW3AAM | EC3: INVALID_FIELD_FOR_INSERT_UPDATE: Unable to create/update fields: APTS_Product_Id_18__c, Type. Please check the security settings of this field and verify that it is read/write for your profile or permission set. [APTS_Product_Id_18__c, Type]
A4: [Product2] | B4: Verified Mark Certificate | C4: 99-san | E4: TRUE | F4: DigiCert | G4: USD | H4: 012dp000005zfL7AAI | J4: 01t4z000008iBW4AAM | K4: 01t4z000008iBW4AAM | L4: 01t4z000008iBW4AAM | U4: TRUE | W4: TRUE | X4: Commercial | Y4: FALSE | BF4: FALSE | CC4: FALSE | CF4: FALSE | CK4: FALSE | CL4: FALSE | CM4: FALSE | CO4: 01tWC00000AYBXzYAP | CQ4: FALSE | CU4: FALSE | CW4: FALSE | CX4: FALSE | CZ4: FALSE | DA4: FALSE | DH4: FALSE | DM4: 99-san | DP4: FALSE | DR4: FALSE | DT4: Verified Mark Certificate | DY4: Active | DZ4: Failed | EA4: 01t4z000008iBW4AAM | EC4: INVALID_FIELD_FOR_INSERT_UPDATE: Unable to create/update fields: APTS_Product_Id_18__c, Type. Please check the security settings of this field and verify that it is read/write for your profile or permission set. [APTS_Product_Id_18__c, Type]
A5: [Product2] | B5: Code Signing (Units) | C5: Code Signing (Units) | E5: TRUE | F5: DigiCert | G5: USD | H5: 012dp000005zfL7AAI | J5: 01t4z000008jjfJAAQ | K5: 01t4z000008jjfJAAQ | L5: 01t4z000008jjfJAAQ | U5: TRUE | V5: Allowed | W5: TRUE | X5: Commercial | Y5: FALSE | BF5: FALSE | CC5: FALSE | CF5: FALSE | CK5: FALSE | CL5: FALSE | CM5: FALSE | CO5: 01tWC00000AYBY1YAP | CQ5: FALSE | CU5: FALSE | CW5: FALSE | CX5: FALSE | CZ5: FALSE | DA5: FALSE | DH5: FALSE | DM5: Code Signing (Units) | DP5: FALSE | DR5: FALSE | DT5: Code Signing (Units) | DY5: Active | DZ5: Failed | EA5: 01t4z000008jjfJAAQ | EC5: INVALID_FIELD_FOR_INSERT_UPDATE: Unable to create/update fields: APTS_Product_Id_18__c, Type. Please check the security settings of this field and verify that it is read/write for your profile or permission set. [APTS_Product_Id_18__c, Type]
A6: [Product2] | B6: Authentication Only | C6: Authentication Only | E6: TRUE | F6: DigiCert | G6: USD | H6: 012dp000005zfL7AAI | J6: 01t0z000007f40zAAA | K6: 01t0z000007f40zAAA | L6: 01t0z000007f40zAAA | R6: 11BWC000002WLhn2AG | U6: TRUE | V6: Allowed | W6: TRUE | X6: Commercial | Y6: FALSE | BF6: FALSE | CC6: FALSE | CF6: FALSE | CK6: FALSE | CL6: FALSE | CM6: FALSE | CO6: 01tWC00000AYBY2YAP | CQ6: FALSE | CU6: FALSE | CW6: FALSE | CX6: FALSE | CZ6: FALSE | DA6: FALSE | DH6: FALSE | DM6: Authentication Only | DP6: FALSE | DR6: FALSE | DT6: Authentication Only | DY6: Active | DZ6: Failed | EA6: 01t0z000007f40zAAA | EC6: INVALID_FIELD_FOR_INSERT_UPDATE: Unable to create/update fields: APTS_Product_Id_18__c, Type. Please check the security settings of this field and verify that it is read/write for your profile or permission set. [APTS_Product_Id_18__c, Type]
